Workbook

Sheet Evaluación_ideas
B2: EVALUACIÓN DE IDEAS DE NEGOCIO
B3: FORMATO DE DESCRIPCIÓN DE IDEAS DE NEGOCIO
B4: No | C4: Nombre de la Idea del Negocio | D4: Fuente de Identificación de la Idea del Negocio | E4: Breve descripción de la Idea del Negocio | F4: Principal Razon Por la que Puede Ser Una Idea Ganadora
B5: 1 | C5: Turismo Senior | D5: Tendencia demográfica y notas de prensa sobre el auge de viajes 60+; escasez de paquetes accesibles | E5: Agencia que diseña y opera viajes “slow” con logística médica, guías formados y destinos fuera de temporada | F5: Mercado en rápido crecimiento y capacidad de desestacionalizar la oferta turística, generando ingresos todo el año
B6: 2 | C6: Asistente Virtual para la Tercera Edad | D6: Reportes sobre soledad no deseada y adopción de interfaces de voz | E6: Altavoz/app IA que recuerda medicación, conecta con voluntarios y monitorea bienestar | F6: Alta necesidad social, barreras de salida altas una vez el usuario adopta la plataforma (stickiness)
B7: 3 | C7: Centro de Acondicionamiento Senior | D7: Datos OMS/Ministerio sobre sedentarismo > 50 % en mayores | E7: Gimnasio boutique con programas gerontológicos, monitoreo médico y convenios EPS | F7: Convierte un problema de salud pública en ingresos recurrentes; posibilidad de cofinanciación por aseguradoras
B8: 4 | C8: ActivaVida – Dispositivo de Equilibrio y Reflejos | D8: Estadísticas de caídas (1 de 3 mayores/año) y papers de propiocepción | E8: Ecosistema de dispositivos modulares (disco IMU, banda, pads) + app y analítica para fisios | F8: Hardware low‑cost + servicio SaaS: alto impacto clínico, ingresos por venta y suscripción
B9: 5 | C9: Snacks Nutricionales Senior | D9: Estudios sobre anorexia de la edad y sarcopenia | E9: Línea de bocados blandos, ricos en proteína y fibra, bajos en azúcar y sal | F9: Nicho poco atendido; sinergia con farmacias/geriátricos y tendencia “healthy aging”
B10: 6 | C10: Huertos Intergeneracionales | D10: Programas municipales de huertas y evidencias de integración social | E10: Instalación y mentoría de huertas urbanas que reúnen jóvenes y mayores | F10: Alto impacto social y bajo costo operativo; elegible a subvenciones públicas
B11: 7 | C11: AbueloAmigo | D11: Iniciativas como “Voces en Red” y redes de voluntariado locales | E11: Plataforma que empareja seniors con voluntarios para llamadas y salidas | F11: Escalable digitalmente y con costes de infraestructura mínimos
B12: 8 | C12: SeniorGames | D12: Meta‑análisis de exergames que mejoran equilibrio y cognición | E12: Consola/app de juegos adaptativos con sensores de movimiento y niveles ajustables | F12: Combina entretenimiento y salud, mercado global de “seniors games” al alza
B13: 9 | C13: Puertas Inteligentes Seguras | D13: Estadísticas de caídas y accidentes domésticos en adultos mayores; artículos sobre automatización del hogar y estudios que muestran aceptación de monitoreo por parte de seniors | E13: Cerraduras y sensores inteligentes que impiden quedar encerrado, alertan caídas en el marco de la puerta y permiten apertura remota por familiares o cuidadores | F13: Resuelve un dolor crítico (seguridad en el hogar) con tecnología ya madura y con alta disposición de pago; se integra fácilmente a ecosistemas de smart‑home y genera ingresos recurrentes por monitoreo y mantenimiento
B14: 10
B15: 11
B16: 12
B17: 13
B18: 14

Sheet Valoración-ideas
B2: EVALUACION DE IDEAS DE NEGOCIO
B3: FORMATO DE EVALUACION DE IDEAS DE NEGOCIO
B4: No | C4: Idea de Negocio | D4: Perspectiva Personal | I4: Perspectiva de Mercado | Q4: Perspectiva de Recursos | W4: Perspectiva Legal
C5: CRITERIOS DE EVALUACIÓN 5 - Totalmente 4 - En un alto porcentaje 3 - En un porcentaje aceptable 2 - Muy poco 1 - Nada | D5: Vibro con la idea me gusta mucho | E5: Tengo el talento para sacar la idea adelante | F5: Tengo conocimiento en este campo | G5: Poseo experiencia practica | H5: Tengo red de contactos | I5: El producto sería valorado por el mercado final | J5: Tiene potencial en el mercado | K5: Estabilidad del mercado en ciclos económicos | L5: Incremento proyectado del número de consumidores (población consumidora en aumento) | M5: La idea busca atender necesidades insatisfechas | N5: Conozco la competencia | O5: Sé Como podría llegar al mercado objetivo | P5: La idea tiene elementos innovadores, diferenciadores | Q5: Tiene capacidad de conseguir un equipo con el perfil requerido | R5: Tengo acceso a la tecnología requerida | S5: Puedo conseguir los insumos y materia prima requerida | T5: asegurado el suministro de materias primas, (disponibilidad estable, bajos costos) | U5: cuento con los recursos económicos y/o posibles fuentes de financiación | V5: El negocio Puede ser rentable | W5: Aspectos legales | X5: Patentes, licencias | Y5: Legislación controles ambientales | Z5: TOTAL | AC5: ,
B6: 1 | C6: Turismo Senior | D6: =(3+4+5+4)/4 -> 4 | E6: =(2+3+2+2)/4 -> 2.25 | F6: =(2+1+2+1)/4 -> 1.5 | G6: =(2+1+1+1)/4 -> 1.25 | H6: =(2+2+3+3)/4 -> 2.5 | I6: =(3+3+4+3)/4 -> 3.25 | J6: =(3+4+5+3)/4 -> 3.75 | K6: =(3+4+4+4)/4 -> 3.75 | L6: =(4+5+5+5)/4 -> 4.75 | M6: =(4+5+4+5)/4 -> 4.5 | N6: =(2+1+2+1)/4 -> 1.5 | O6: =(2+5+4+2)/4 -> 3.25 | P6: =(2+3+3+3)/4 -> 2.75 | Q6: =(4+4+4+4)/4 -> 4 | R6: =(4+1+4+1)/4 -> 2.5 | S6: =(4+4+4+4)/4 -> 4 | T6: =(3+3+3+4)/4 -> 3.25 | U6: =(1+1+1+1)/4 -> 1 | V6: =(3+4+4+3)/4 -> 3.5 | W6: =(4+3+2+3)/4 -> 3 | X6: =(3+3+3+3)/4 -> 3 | Y6: =(4+5+5+4)/4 -> 4.5 | Z6: =AVERAGE(D6:Y6) -> 3.0795455
B7: 2 | C7: Asistente Virtual para la Tercera Edad | D7: =(3+4+5+4)/4 -> 4 | E7: =(5+3+2+4)/4 -> 3.5 | F7: =(4+1+2+3)/4 -> 2.5 | G7: =(4+1+1+3)/4 -> 2.25 | H7: =(2+2+3+3)/4 -> 2.5 | I7: =(3+3+4+3)/4 -> 3.25 | J7: =(3+4+5+4)/4 -> 4 | K7: =(3+4+4+4)/4 -> 3.75 | L7: =(4+5+5+5)/4 -> 4.75 | M7: =(4+5+4+5)/4 -> 4.5 | N7: =(2+1+2+1)/4 -> 1.5 | O7: =(2+5+4+3)/4 -> 3.5 | P7: =(2+3+3+3)/4 -> 2.75 | Q7: =(4+4+4+4)/4 -> 4 | R7: =(4+1+4+4)/4 -> 3.25 | S7: =(4+4+4+4)/4 -> 4 | T7: =(4+3+3+4)/4 -> 3.5 | U7: =(4+1+1+1)/4 -> 1.75 | V7: =(2+4+4+3)/4 -> 3.25 | W7: =(4+3+2+4)/4 -> 3.25 | X7: =(4+3+3+3)/4 -> 3.25 | Y7: =(4+5+5+4)/4 -> 4.5 | Z7: =AVERAGE(D7:Y7) -> 3.3409091
B8: 3 | C8: Centro de Acondicionamiento Senior | D8: =(3+4+5+5)/4 -> 4.25 | E8: =(2+3+2+3)/4 -> 2.5 | F8: =(2+2+2+3)/4 -> 2.25 | G8: =(2+3+1+3)/4 -> 2.25 | H8: =(2+1+3+2)/4 -> 2 | I8: =(3+4+4+4)/4 -> 3.75 | J8: =(3+1+5+4)/4 -> 3.25 | K8: =(3+2+4+4)/4 -> 3.25 | L8: =(4+5+5+5)/4 -> 4.75 | M8: =(3+5+4+5)/4 -> 4.25 | N8: =(3+1+2+1)/4 -> 1.75 | O8: =(2+5+4+3)/4 -> 3.5 | P8: =(2+1+3+3)/4 -> 2.25 | Q8: =(2+1+4+4)/4 -> 2.75 | R8: =(2+1+4+4)/4 -> 2.75 | S8: =(3+1+4+4)/4 -> 3 | T8: =(3+1+3+4)/4 -> 2.75 | U8: =(1+1+1+1)/4 -> 1 | V8: =(3+1+4+3)/4 -> 2.75 | W8: =(4+1+2+3)/4 -> 2.5 | X8: =(3+3+3+3)/4 -> 3 | Y8: =(4+5+5+4)/4 -> 4.5 | Z8: =AVERAGE(D8:Y8) -> 2.9545455
B9: 4 | C9: ActivaVida – Dispositivo de Equilibrio y Reflejos | D9: =(5+3+5+4)/4 -> 4.25 | E9: =(5+2+3+2)/4 -> 3 | F9: =(4+1+2+2)/4 -> 2.25 | G9: =(4+1+1+1)/4 -> 1.75 | H9: =(3+1+3+3)/4 -> 2.5 | I9: =(4+3+5+3)/4 -> 3.75 | J9: =(4+2+5+4)/4 -> 3.75 | K9: =(4+2+5+4)/4 -> 3.75 | L9: =(5+5+5+5)/4 -> 5 | M9: =(4+3+5+5)/4 -> 4.25 | N9: =(3+1+2+1)/4 -> 1.75 | O9: =(4+4+4+2)/4 -> 3.5 | P9: =(5+2+4+4)/4 -> 3.75 | Q9: =(4+1+4+4)/4 -> 3.25 | R9: =(4+1+4+3)/4 -> 3 | S9: =(4+2+4+4)/4 -> 3.5 | T9: =(3+3+4+4)/4 -> 3.5 | U9: =(4+1+4+1)/4 -> 2.5 | V9: =(4+3+4+3)/4 -> 3.5 | W9: =(4+3+2+3)/4 -> 3 | X9: =(4+4+2+3)/4 -> 3.25 | Y9: =(4+5+5+4)/4 -> 4.5 | Z9: =AVERAGE(D9:Y9) -> 3.3295455
B10: 5 | C10: Snacks Nutricionales Senior | D10: =(2+4+1+4)/4 -> 2.75 | E10: =(2+3+1+2)/4 -> 2 | F10: =(1+2+1+3)/4 -> 1.75 | G10: =(1+1+1+2)/4 -> 1.25 | H10: =(2+1+3+2)/4 -> 2 | I10: =(3+3+4+3)/4 -> 3.25 | J10: =(2+4+2+3)/4 -> 2.75 | K10: =(3+4+2+4)/4 -> 3.25 | L10: =(4+5+5+5)/4 -> 4.75 | M10: =(2+5+4+5)/4 -> 4 | N10: =(2+1+1+2)/4 -> 1.5 | O10: =(1+5+2+2)/4 -> 2.5 | P10: =(2+3+2+3)/4 -> 2.5 | Q10: =(2+4+4+4)/4 -> 3.5 | R10: =(2+1+4+2)/4 -> 2.25 | S10: =(4+4+4+4)/4 -> 4 | T10: =(3+3+2+4)/4 -> 3 | U10: =(1+1+1+1)/4 -> 1 | V10: =(3+4+2+3)/4 -> 3 | W10: =(2+3+1+3)/4 -> 2.25 | X10: =(3+3+2+3)/4 -> 2.75 | Y10: =(3+5+2+4)/4 -> 3.5 | Z10: =AVERAGE(D10:Y10) -> 2.7045455
B11: 6 | C11: Huertos Intergeneracionales | D11: =(2+4+2+4)/4 -> 3 | E11: =(1+3+2+2)/4 -> 2 | F11: =(1+1+2+1)/4 -> 1.25 | G11: =(1+1+1+1)/4 -> 1 | H11: =(2+2+1+3)/4 -> 2 | I11: =(3+3+4+3)/4 -> 3.25 | J11: =(3+4+2+3)/4 -> 3 | K11: =(2+4+2+4)/4 -> 3 | L11: =(4+5+5+5)/4 -> 4.75 | M11: =(2+5+2+5)/4 -> 3.5 | N11: =(2+1+2+1)/4 -> 1.5 | O11: =(2+5+4+2)/4 -> 3.25 | P11: =(2+3+2+3)/4 -> 2.5 | Q11: =(2+4+4+4)/4 -> 3.5 | R11: =(4+1+5+1)/4 -> 2.75 | S11: =(4+4+5+4)/4 -> 4.25 | T11: =(2+3+5+4)/4 -> 3.5 | U11: =(1+1+4+1)/4 -> 1.75 | V11: =(3+4+2+3)/4 -> 3 | W11: =(3+3+4+3)/4 -> 3.25 | X11: =(3+3+5+3)/4 -> 3.5 | Y11: =(4+5+5+4)/4 -> 4.5 | Z11: =AVERAGE(D11:Y11) -> 2.9090909
B12: 7 | C12: AbueloAmigo | D12: =(2+4+5+4)/4 -> 3.75 | E12: =(2+3+4+3)/4 -> 3 | F12: =(2+1+4+3)/4 -> 2.5 | G12: =(1+1+1+3)/4 -> 1.5 | H12: =(2+2+2+2)/4 -> 2 | I12: =(3+3+4+3)/4 -> 3.25 | J12: =(3+4+4+3)/4 -> 3.5 | K12: =(3+4+4+4)/4 -> 3.75 | L12: =(4+5+5+5)/4 -> 4.75 | M12: =(4+5+4+5)/4 -> 4.5 | N12: =(2+1+1+1)/4 -> 1.25 | O12: =(2+5+2+2)/4 -> 2.75 | P12: =(2+3+2+3)/4 -> 2.5 | Q12: =(4+4+4+4)/4 -> 4 | R12: =(4+1+4+1)/4 -> 2.5 | S12: =(4+4+4+4)/4 -> 4 | T12: =(2+3+4+4)/4 -> 3.25 | U12: =(1+1+1+1)/4 -> 1 | V12: =(2+4+4+3)/4 -> 3.25 | W12: =(4+3+4+3)/4 -> 3.5 | X12: =(3+3+5+3)/4 -> 3.5 | Y12: =(4+5+5+4)/4 -> 4.5 | Z12: =AVERAGE(D12:Y12) -> 3.1136364
B13: 8 | C13: SeniorGames | D13: =(4+4+5+4)/4 -> 4.25 | E13: =(4+4+4+3)/4 -> 3.75 | F13: =(2+2+3+3)/4 -> 2.5 | G13: =(1+1+1+2)/4 -> 1.25 | H13: =(2+3+4+2)/4 -> 2.75 | I13: =(3+5+4+4)/4 -> 4 | J13: =(3+5+5+4)/4 -> 4.25 | K13: =(3+3+5+4)/4 -> 3.75 | L13: =(4+5+5+5)/4 -> 4.75 | M13: =(4+5+5+5)/4 -> 4.75 | N13: =(2+3+1+1)/4 -> 1.75 | O13: =(2+5+4+3)/4 -> 3.5 | P13: =(2+5+5+4)/4 -> 4 | Q13: =(4+4+5+4)/4 -> 4.25 | R13: =(4+2+5+3)/4 -> 3.5 | S13: =(4+4+4+4)/4 -> 4 | T13: =(3+3+5+4)/4 -> 3.75 | U13: =(1+1+1+1)/4 -> 1 | V13: =(3+5+5+3)/4 -> 4 | W13: =(4+3+5+3)/4 -> 3.75 | X13: =(3+3+4+3)/4 -> 3.25 | Y13: =(4+5+5+4)/4 -> 4.5 | Z13: =AVERAGE(D13:Y13) -> 3.5113636
B14: 9
B15: 10
B16: 11
B17: 12
B18: 13
B19: 14
B20: 15
C21: EJEMPLOS
C22: Servicio de correo para tiendas y pequeños negocios | D22: 5 | E22: 5 | F22: 4 | G22: 4 | H22: 5 | I22: 4 | J22: 4 | K22: 5 | L22: 3 | M22: 4 | N22: 3 | O22: 2 | P22: 3 | Q22: 4 | R22: 3 | S22: 5 | T22: 4 | U22: 4 | V22: 4 | W22: 5 | X22: 4 | Y22: 5 | Z22: =AVERAGE(D22:Y22) -> 4.0454545
C23: Producción y venta de bocadillo dietético | D23: 3 | E23: 3 | F23: 2 | G23: 2 | H23: 4 | I23: 5 | J23: 4 | K23: 5 | L23: 5 | M23: 3 | N23: 2 | O23: 2 | P23: 4 | Q23: 5 | R23: 4 | S23: 5 | T23: 5 | U23: 4 | V23: 3 | W23: 5 | X23: 3 | Y23: 4 | Z23: =AVERAGE(D23:Y23) -> 3.7272727
B24: * Para obtener el total, se suman todos los puntajes de la idea y se dividen por 22 (total de factores que se califican)

Sheet IdeavsEstrategia
B2: Proyecto Vs Estrategia Organizacional
B3: Objetivo: | C3: Identificar la relación existente entre la Idea de Proyecto y la Estrategia Organizacional
B4: Componentes | D4: Preguntas | E4: Detalles
B5: PERSPECTIVA (POR QUE) | C5: Antecedentes de negocio | D5: Por que debemos hacer el proyecto? | E5: Quien es el cliente/Usuario
D6: Cual es la perspectiva de negocio y la motivación? | E6: Cual es su necesidad?
E7: Como lograremos satisfacer esa necesidad?
E8: Cual es la oportunidad de negocio?
C9: Objetivo de negocio | D9: Que queremos conseguir como negocio? | E9: Cual es la meta de negocio que se conseguirá una vez el resultado del proyecto sea generado?
C10: Concepto estratégico | D10: Por que el proyecto soportara la estrategia de negocios de la compañía? | E10: Cual es el principio de solución estratégico que guiara el plan y la ejecución del proyecto y soportara la estrategia de la compañía?
D11: Cual es la idea competitiva estratégica?
B12: POSICION (QUE) | C12: Definición de producto | D12: Cual es el producto que será creado o producido por el proyecto? | E12: Que vamos a producir?
E13: Que tipo de producto es?
E14: Cual es su concepto de operación y sus principales características?
C15: Ventaja Competitiva/Valor | D15: Que tan bueno es? | E15: Cual es la ventaja para el cliente/usuario sobre:
D16: Por que es mejor que sus competidores? | E16: Competidores ?
D17: Por que es mejor que el proceso/estado actual? | E17: Productos previos?
D18: Por que el cliente lo compraría? | E18: Soluciones Alternativas?
D19: Cual es el valor para nosotros? | E19: Costo/Efectividad del producto, como podría beneficiarnos?
C20: Criterios de éxito/falla | D20: Cuales son las expectativas? | E20: Cuales son las dimensiones del éxito y sus indicadores?
D21: Como mediremos el éxito del proyecto?
D22: Que puede ir mal? | E22: Cuales son los principales riesgos y sus consecuencias?
B24: Proyecto Vs Estrategia Organizacional
B25: Objetivo: | C25: Identificar la relación existente entre la Idea de Proyecto y la Estrategia Organizacional
B26: Componentes | D26: Preguntas | E26: Detalles
B27: PERSPECTIVA (POR QUE) | C27: Antecedentes de negocio | D27: Altas tasas de caídas en adultos mayores (1 de cada 3 al año), aumento del sedentarismo y deterioro cognitivo. Costos sanitarios por caídas cercanos al 1% del PIB en Colombia. | E27: Adultos mayores (60+), cuidadores/familias, clínicas y fisioterapeutas, EPS y aseguradoras.
D28: El envejecimiento poblacional (20% de mayores en 2040) exige soluciones accesibles de prevención y monitoreo en el hogar. | E28: Prevenir caídas y deterioro cognitivo con herramientas motivadoras y accesibles, con datos clínicos confiables para la toma de decisiones médicas.
E29: Mediante un ecosistema de dispositivos lúdicos + app móvil + portal de analítica clínica con seguimiento remoto.
E30: Mercado TAM en Colombia de alrededor de 500 M (USD); crecimiento anual de 13% en tele-rehabilitación en LatAm; escasez de competidores que integren hardware low-cost, gamificación y datos clínicos.
C31: Objetivo de negocio | D31: Meta de 10.000 usuarios activos y 50 clínicas aliadas en 24 meses; reducir en 15% las caídas y mejorar en 20% el tiempo de reacción en usuarios. | E31: Cual es la meta de negocio que se conseguirá una vez el resultado del proyecto sea generado?
C32: Concepto estratégico | D32: Refuerza la visión de ser plataforma líder en salud activa y preventiva para adultos mayores, integrando IoT y analítica clínica accesible. | E32: Modelo Device-as-a-Service (kits en arriendo o venta + suscripción digital).
D33: Hardware modular low-cost, gamificación social y reportes clínicos automatizados que mejoran adherencia y diferencian frente a apps solo-software o equipos clínicos premium. | K33: 0 | L33: 5 | M33: 4 | N33: 5 | O33: =SUM(E33:N33)/10 -> 1.4
B34: POSICION (QUE) | C34: Definición de producto | D34: Ecosistema compuesto por: banda IMU, disco de equilibrio, pads táctiles, app móvil (React Native), backend analítico y portal clínico. | E34: Kits físicos + plataforma digital + servicio de suscripción y analítica.
E35: Solución integrada de hardware + software + servicio (salud digital).
E36: Plug-and-play, retos lúdicos guiados, feedback visual/háptico, conectividad cloud, reportes clínicos automáticos.
C37: Ventaja Competitiva/Valor | D37: Ofrece prevención medible, divertida y accesible. | E37: Cual es la ventaja para el cliente/usuario sobre:
D38: Competidores: apps solo-software (sin métricas físicas); plataformas clínicas premium (muy costosas, solo para hospitales). ActivaVida ofrece bajo costo + usabilidad en el hogar. | E38: Competidores ?
D39: Estado actual: fisioterapia presencial limitada, sin datos objetivos en casa. La solución permite prevención diaria, adherencia y evidencia clínica. | E39: Productos previos?
D40: Porque reduce riesgo de caídas y deterioro cognitivo, mejora la autonomía, genera confianza familiar y datos útiles para médicos/EPS. | E40: Soluciones Alternativas?
D41: Márgenes 40% en hardware, ingresos recurrentes por suscripción SaaS, expansión de portafolio B2B con analítica para aseguradoras. | E41: Costo/Efectividad del producto, como podría beneficiarnos?
C42: Criterios de éxito/falla | D42: Impacto clínico: reducción 15% caídas y mejora 20% reflejos. Negocio: ARR > USD 2M al año 2. Uso: 8.000 MAU al mes 18. | E42: Cuales son las dimensiones del éxito y sus indicadores?
...

Sheet Arbol Problemas
B2: ÁRBOL DEL PROBLEMAS
B4: Efectos Indirectos | D4: Disminución de la esperanza de vida saludable | F4: Aumento de la carga familiar y "cuidadores" | H4: Reducción de participación en actividades comunitarias | L4: Mayor dependencia de servicios asistenciales | AF4: ÁRBOL DE PROBLEMAS
B6: Efectos Indirectos | D6: Estrés económico en familias | F6: Aumento de depresión | H6: Pérdida de autonomía personal | L6: Sobrecarga de EPS y clínicas | AF6: Efectos Indirectos | AH6: Disminución de participación en el mercado | AJ6: Pérdida de competitividad frente a rivales | AL6: Reducción de ingresos y rentabilidad
R7: 🔽 Causas (raíces):
B8: Efectos Indirectos | D8: Mayor riesgo de aislamiento social | F8: Deterioro de la autoestima | H8: Deterioro cognitivo acelerado | L8: Reducción del bienestar general | R8: 1 | S8: Falta de planeación urbana para el crecimiento vehicular | AF8: Efectos Indirectos | AH8: Clientes migran hacia la competencia | AJ8: Disminución de confianza de inversionistas | AL8: Pérdida de posicionamiento en el sector
R9: 2 | S9: Ausencia de políticas de control de parqueo en vía pública
B10: Efectos Directos | C10: . | D10: Aumento de costos sanitarios | H10: Fracturas y lesiones graves | J10: Periodos de recuperación más largos | L10: Reducción de movilidad y equilibrio | R10: 3 | S10: Poca inversión en infraestructura de parqueaderos públicos | AF10: Efectos Indirectos | AH10: Desaprovechamiento de tendencias tecnológicas | AJ10: Reputación debilitada ante stakeholders | AL10: Menor capacidad de innovación
R11: 4 | S11: Alta densidad vehicular en zonas comerciales y residenciales
B12: Problema Central | D12: Falta de herramientas y procesos efectivos para la prevención de caídas en adultos mayores, con baja continuidad y escaso seguimiento de datos clínicos. | R12: 5 | S12: Débil regulación de construcciones sin áreas de estacionamiento | AF12: Efectos Directos | AG12: . | AH12: Estrategias de marketing poco alineadas con el mercado | AJ12: Pérdida de oportunidades comerciales | AL12: Baja efectividad de campañas publicitarias
R13: 🔼 Efectos (consecuencias):
B14: Causas Directas | D14: Ineficacia en tratamientos médicos | F14: Falta de monitoreo remoto | H14: Ausencia de programas lúdicos | L14: Escaso acceso a tecnología adaptada a necesidades particulares | R14: 1 | S14: Mayor congestión vehicular en zonas críticas | AF14: Problema Central | AH14: La empresa carece de procesos efectivos para identificar y aprovechar oportunamente las oportunidades y tendencias de mercado, lo que limita la eficacia de sus estrategias de marketing.
R15: 2 | S15: Reducción de la movilidad urbana y aumento del tiempo de desplazamiento
B16: Causas Indirectas | D16: Demora para diágnosticos de enfermedades degenerativas y resultados | H16: Diagnóstico tardío | J16: Escasez de profesionales especializados | L16: Diagnósticos tardíos de enfermedades degenerativas | R16: 3 | S16: Invasión del espacio público por vehículos mal estacionados | AF16: Causas Directas | AH16: Falta de sistemas de análisis de datos en tiempo real | AJ16: Procesos de toma de decisiones lentos y burocráticos | AL16: Escasa cultura de innovación
R17: 4 | S17: Disminución de la calidad de vida de los residentes
B18: Causas Indirectas | D18: Demora entre citas | H18: Demoras en asignación de citas | J18: Protocolos de prevención desactualizados | L18: Falta de innovación tecnológica accesible | R18: 5 | S18: Pérdidas económicas para comercios locales por dificultad de acceso | AF18: Causas Indirectas | AH18: Dependencia de estudios de mercado tradicionales y desactualizados | AJ18: Limitada inversión en herramientas tecnológicas | AL18: Escasez de personal especializado en análisis de tendencias
B20: Causas Indirectas | D20: Hay falta de profesionales en el sector salud | H20: Desigualdad en cobertura de programas de prevención | J20: Baja cultura de envejecimiento activo y hábitos de ejercicio en mayores | L20: Escasa industria de dispositivos de salud en el país | AF20: Causas Indirectas | AH20: Falta de integración de fuentes de datos internas y externas | AJ20: Ausencia de metodologías ágiles en gestión estratégica | AL20: Escasa colaboración interdepartamental
B22: Causas Indirectas | D22: Saturación en el sector salud | H22: Falta de incentivos a innovación para prevención | J22: Escaso apoyo a desarrollo de talento en geriatría y fisioterapia | L22: Poca articulación entre gobierno, EPS y sector privado | AF22: Causas Indirectas | AH22: Poca inversión en I+D aplicada al marketing | AJ22: Desconexión con universidades o centros de innovación | AL22: Falta de incentivos para la innovación organizacional

Sheet Marco logico
B2: METODOLOGÍA MARCO LÓGICO
B7: 1. IDENTIFICAR EL PROBLEMA
B9: Existe una falta de herramientas y procesos efectivos para prevenir caídas y deterioro cognitivo en adultos mayores. Esta situación genera baja continuidad en los tratamientos, escaso seguimiento de datos clínicos, y un incremento en la dependencia, costos de atención y deterioro de la calidad de vida.
B18: 2. ANALIZAR GRUPOS DE INTERES O INVOLUCRADOS DEL PROYECTO
B19: https://ingenioempresa.com/analisis-involucrados-marco-logico/
B21: a. Elaboración de la tabla de participación (identificar los interesados)
B22: b. Definir los roles y su participacion
B24: a. Indentificacion de interesados Diagnostico de la población afectada y del entorno en general | C24: b. Roles y su participacion | N24: Ejemplo de categorizacion de los interesados
B25: Grupos | C25: Roles de los actores | D25: Tipo de participacion | E25: Intereses | F25: Problemáticas | H25: Recursos/ Mandatos
B26: 1. Org. Del sector publico | C26: Cooperante/Beneficiario | D26: Informar/asesorar | E26: Reducir carga al sistema de salud; promover envejecimiento activo | F26: Saturación en el sistema de salud; falta de innovación preventiva | H26: Políticas públicas, financiación estatal, normativas de salud | N26: Roles de los actores | O26: Tipo de participacion
B27: 2. Org. Del sector privado | C27: Beneficiario | D27: Informar | E27: Acceso a nuevos mercados, reputación social, inversión en salud preventiva | F27: Falta de acceso a datos clínicos para desarrollar soluciones | H27: Inversión, tecnología, canales de distribución | N27: Cooperante | O27: Informar
B28: 3. Org. Del sector sociedad civil | C28: Cooperante | D28: Aliado | E28: Mejorar calidad de vida de mayores; participación comunitaria | F28: Baja cultura de envejecimiento activo; aislamiento social | H28: Programas sociales, redes comunitarias | N28: Beneficiario | O28: Asesorar
B29: 4. Org. Religiosas | C29: Afectados | D29: consultar | E29: Bienestar integral de sus adultos mayores; red de apoyo espiritual\ | F29: Escasa inclusión de sus miembros en estrategias de salud | H29: Voluntariado, espacios comunitarios | N29: Afectados | O29: Aliado
B30: 5. Org. Externas | C30: opositor | D30: control | E30: Verificar impactos sociales, éticos y regulatorios | F30: Preocupaciones por privacidad, sostenibilidad y equidad en acceso tecnológico | H30: Organismos internacionales, ONGs, reguladores externos | N30: opositor | O30: consultar
B33: c. Agruparlos y priorizarlos
B35: Criterio | C35: Calificacion grupo
B36: ALTO | C36: 3
B37: MEDIO | C37: 2
B38: BAJO | C38: 1
B41: d. Analizar grupos de interes
B43: Criterio de Selección | C43: Peso del criterio | D43: Grupo 1 | F43: Grupo 2 | H43: Grupo 3 | J43: Grupo 4 | L43: Grupo 5
D44: Calificacion | E44: Resultado | F44: Calificacion | G44: Resultado | H44: Calificacion | I44: Resultado | J44: Calificacion | K44: Resultado | L44: Calificacion | M44: Resultado
B45: PODER | C45: 0.5 | D45: 3 | E45: =+D45*C45 -> 1.5 | F45: 3 | G45: =+C45*F45 -> 1.5 | H45: 3 | I45: =C45*H45 -> 1.5 | J45: 1 | K45: =$C$45*J45 -> 0.5 | L45: 2 | M45: =$C$45*L45 -> 1
B46: INTERES | C46: 0.3 | D46: 2 | E46: =+D46*C46 -> 0.6 | F46: 2 | G46: =+C46*F46 -> 0.6 | H46: 1 | I46: =C46*H46 -> 0.3 | J46: 2 | K46: =$C$45*J46 -> 1 | L46: 1 | M46: =$C$45*L46 -> 0.5
B47: INFLUENCIA | C47: 0.2 | D47: 3 | E47: =+D47*C47 -> 0.6 | F47: 3 | G47: =+C47*F47 -> 0.6 | H47: 1 | I47: =+C47*H47 -> 0.2 | J47: 1 | K47: =$C$45*J47 -> 0.5 | L47: 1 | M47: =$C$45*L47 -> 0.5
B48: Totales | C48: =SUM(C45:C47) -> 1 | D48: Subtotal Grupo 1 | E48: =SUM(E45:E47) -> 2.7 | F48: Subtotal Grupo 2 | G48: =SUM(G45:G47) -> 2.7 | H48: Subtotal Grupo 3 | I48: =SUM(I45:I47) -> 2 | J48: Subtotal Grupo 3 | K48: =SUM(K45:K47) -> 2 | L48: Subtotal Grupo 3 | M48: =SUM(M45:M47) -> 2
B51: e. Matriz -Valorando los involucrados (Poder e interes) Agrupa a los interesados basándose en su nivel de autoridad para controlar las decisiones de un proyecto, facilitar su ejecución o dificultarla –económica-política-social etc. (“poder”) y su nivel de preocupación (“interés”) con respecto a los resultados del proyecto. | F51: e. Matriz -Valorando los involucrados (Influencia e Impacto) Agrupa a los interesados basándose en su participación activa (“influencia”) en el proyecto y su capacidad de efectuar cambios a la planificación o ejecución del proyecto (“impacto”).
F55: INFLUENCIA | G55: ALTA
J56: Org. del sector privado; Org. del sector público
H60: Org. religiosas; Org. externas / ONGs / reguladores | J60: Org. sociedad civil
G61: BAJA
H65: BAJA | J65: ALTA
H66: IMPACTO
B69: e. Establecer estrategias con el involucrado
B71: Grupos | C71: Estrategia
B72: 1. Org. Del sector publico | C72: Involucramiento activo y sostenido. Facilitar toma de decisiones y coordinación interinstitucional.
B73: 2. Org. Del sector privado | C73: Establecer alianzas estratégicas. Incentivar su participación como co-ejecutores y promotores del proyecto.
B74: 3. Org. Del sector sociedad civil | C74: Fomentar participación ciudadana mediante espacios de diálogo y consulta. Promover mecanismos de veeduría social.
B75: 4. Org. Religiosas | C75: Mantener informadas. Consultas puntuales sobre impacto comunitario.
B76: 5. Org. Externas | C76: Mitigar oposición mediante negociación y transparencia. Escuchar recomendaciones técnicas y asegurar cumplimiento normativo.
...

Sheet Arbol Objetivos
B2: ÁRBOL DE OBJETIVOS
B4: Fines Indirectos | D4: Reducir la saturación del sector salud | F4: Reducción de la carga familiar y de cuidadores | H4: Mayor participación en actividades comunitarias | L4: Menor dependencia de servicios asistenciales
B6: Fines Indirectos | D6: Citas más eficientes | F6: Disminución de casos de depresión en adultos mayores | H6: Mayor autonomía personal | L6: Descongestión de EPS y clínicas
B8: Fines Indirectos | D8: Disminución de costos sanitarios | F8: Incremento de las interacciones sociales | H8: Mantenimiento y mejora de capacidades cognitivas | L8: Aumento del bienestar general | P8: Menores periodos de recuperación | Q8: Disminución de fracturas y lesiones graves | R8: Reducción de los costos sanitarios
B10: Fines Directos | C10: . | D10: Aumento de la calidad de vida aplicando tratamientos médicos en momentos oportunos | H10: Reducción de fracturas y lesiones | J10: Mantenimiento de las funciones cognitivas | L10: Mantenimiento de funciones cognitivas, de movilidad y equilibrio | P10: Menor dependencia de servicios asistenciales | Q10: Mejora en la movilidad y el equilibrio | R10: Disminución de fracturas y lesiones graves
B12: Solución Focal/ Proposito Objetivo General | D12: Desarrollar un sistema integral y accesible que prevenga caídas y el deterioro cognitivo en adultos mayores, incremente la adherencia a los ejercicios, ofrezca monitoreo continuo y genere datos clínicos para una atención oportuna y de calidad.
B14: Objetivos específicos | D14: Aumentar la eficacia de los tratamientos médicos | F14: Implementar monitoreo remoto para seguimiento de pacientes | H14: Diseñar programas lúdicos de mejoras cognitivas y prevención de caídas | L14: Facilitar acceso a tecnología adaptada a necesidades particulares
B16: Medios/ Actividades | D16: Herramienta para generación de datos continuos y un análisis de resultados eficientes | H16: Reducir tiempos de espera en citas médicas | J16: Capacitar profesionales en rehabilitación geriátrica | L16: Desarrollar dispositivos accesibles y de bajo costo
B18: Medios/ Actividades | D18: Hacer las citas más eficientes, mediante la prorización basada en los datos | H18: Mejorar la gestión de agenda médica y priorización de casos | J18: Diseñar campañas de prevención y envejecimiento activo | L18: Incentivar la innovación tecnológica en salud
B20: Medios/ Actividades | D20: Garantizar acceso a la salud facilitando tecnología escalable | H20: Garantizar acceso equitativo a programas preventivos | J20: Fomentar hábitos de ejercicio en adultos mayores | L20: Diseño de herramientas que permitan analizar la aparición y el desarrollo sintomas según los casos estudiados
B22: Medios/ Actividades | D22: Reducir la saturación del sector salud mediante un enfoque en la salud preventiva | H22: Otorgar incentivos para proyectos de prevención en salud | J22: Formar talento especializado en geriatría y fisioterapia | L22: Promover alianzas entre gobierno, aseguradoras y sector privado | P22: Revisión de estudios sobre deterioro cognitivo y lo sintomas que lo acompañan

Sheet Analisis PESTEL
B2: ESTUDIO SECTORIAL - ESTRATEGICO
B4: Análisis PESTEL | J4: Herramienta DOFA | N4: Modelo CAME
B6: Descripción | D6: Factor | F6: Detalle | G6: Plazo | J6: Fortalezas (F): | K6: Oportunidades (O): | L6: Debilidades (D): | M6: Amenazas (A): | N6: Estrategias FO: | O6: Estrategias DO: | P6: Estrategias FA: | Q6: Estrategias DA:
G7: Corto plazo (< 1 mes) | H7: Mediano plazo (1 mes a 3 años) | I7: Largo plazo (> 3 años)
B8: Evalúa de qué forma la intervención del gobierno puede afectar la empresa o el proyecto • Cambios de gobierno y sus programas electorales • Política fiscal • Subsidios del gobierno • Guerras y conflictos • Cambios en legislación • Cambios en los tratados comerciales • Acuerdos internacionales • Conflictos internos y externos • Movimientos políticos | D8: Político | E8: Falta de continuidad en políticas públicas | F8: Se puede reducir el presupuesto y desfinanciar los programas de prevención | G8: x | H8: x | M8: x
E9: Cambios en prioridades en salud | F9: Desviación de recursos hacia otras áreas de salud y seguridad. | G9: x | H9: x | M9: x
E10: Interés de gobiernos locales en reducir costos en salud y dependencia | F10: Programas que buscan disminuir el peso económicoque generan hospitalizaciones. El proyecto se puede alinear a estas metas, facilitando acceso a convenios y subsidios | H10: x | K10: x
E11: Posibilidad de alianzas con EPS | F11: El enfoque de los gobiernos a la atención preventiva es una oportunidad para que las EPS vean el proyecto como una forma de reducir costos a largo plazo | I11: x | J11: x | K11: x
B12: Considera cómo el entorno macroeconómico nacional e internacional puede afectar empresa o el proyecto • Tasas de empleo • Ciclo económico • PIB • Impuestos • Inflación • Decisiones económicas de otros gobiernos • Devaluación y reevaluación de la moneda • Tendencias en canales de distribución • Déficit gubernamental • Índice de confianza del consumidor • Financiación • Proteccionismo de los mercados Por ejemplo, la imposición de aranceles por decisión de Donald Trump sobre Toyota hace parte de una variable económica a tener en cuenta. | D12: Económico | E12: Inflación | F12: Puede afectar la capacidd de pago directo de los usuarios. A pesar de esto, el modelo B2B con las EPS puede amortiguar este riesgo. | H12: x | I12: x | M12: x
E13: Baja capacidad de pago directo de adultos mayores | F13: Baja adopción B2C si faltan convenios o subsidios | G13: x | L13: x
E14: Dependencia de financiamiento externo | F14: El proyecto puede dejar de ser sostenible financieramente si no se consolidan usuarios o alianzas con las entidades de salud | G14: x | L14: x
E15: Modelo de financiación con EPS | F15: El sistema de salud del país permite que las EPS cubran tecnologías de prevención costo-eficientes. Esto abre la oportunidad a la financiación de los dispositivos para los clientes. | H15: x | I15: x | K15: x
E16: Creciente gasto público en salud | F16: Cada caida implica gastos para el sistema de salud. La presentación de este proyecto que busca reducir incidentes puede ser altamente atractiva. | I16: x | K16: x
E17: Crecimiento del mercado potencial | F17: ∼14 % de la población colombiana tiene más de 60 años, y para 2040 se espera que llegue al 20 %. | I17: x | K17: x
B18: Evalúa cultura, religión, creencias, hábitos, preferencias, etc. • Nivel de educación • Modas • Patrones de compra • Creencias • Religiones • Opinión de los clientes • Opiniones o percepción de los medios de información • Estilo de vida • Nivel de ingresos • Nivel de edad | D18: Social | E18: Resistencia al uso de tecnología en adultos mayores | F18: Posiblemente exista una baja adherencia inicial | G18: x | M18: x
E19: Desigualdad en acceso digital | F19: Adultos mayores con bajos ingresos o en zonas alejadas podrían no tener smartphones compatibles | G19: x | H19: x | L19: x
E20: Nivel de educación digital de cuidadores/familiares | F20: Si es bajo, puede frenar la implementación. | G20: x | L20: x
E21: Mayor interés de familias en soluciones accesibles | F21: Mayor busqueda de opciones prácticas que se puedan usar en casa sin necesidad de largos desplazamientos | H21: x | I21: x | K21: x
E22: Mayor adopción digital | F22: El acceso a smartphones en la población general crece cada año, esto permite una curva de aprendizaje más baja. | H22: x | I22: x | K22: x
E23: Valor social de la autonomía | F23: El fuerte componente emocional y cultural en preservar la independencia de adulto mayor. Una propuesta que retrase el deterioro puede ser altamente valorada | G23: x | J23: x
B24: El reto que trae está en que la empresa o los involucrados del proyecto sean consientes de qué tipo de tecnologías la pueden beneficiar o impactar negativamente • Machine Learning • Nuevos códigos de programación • Nueva maquinaria o dispositivos tecnológicos • Impresión 3D • Uso de la energía • Reemplazo de tecnología • Software en la nube • Obsolescencia • Internet • Incentivos por uso de tecnologías | D24: Tecnológico | E24: Obsolescencia tecnológica | F24: La rapidez de innovación obliga a diseñar un dispositivo actualizable y escaclabel para evitar el rezago frente a competidores. | H24: x | I24: x | M24: x
E25: Machine learning | F25: Permite personalizar el nivel deexigencia y adaptarse al progreso del usuario. | G25: x | J25: x
E26: Telemedicina y analítica de datos | F26: El aumento de la atención remota valida la potencialidad que tiene el proyecto al generar reportes en tiempo real. | G26: x | J26: x
E27: Integracion con telefonos móviles | F27: El uso generalizado de smartphones hace que la plataforma sea accesible sin necesidad de hardware muy especializado y costoso. | G27: x | J27: x
E28: Avances en sensores de movimiento | F28: Dispositivos cada vez más pequeños y más económicos que posibilitan medir con precisión. | G28: x | K28: x
B29: Evalúa de qué forma el medio ambiente afecta a la empresa o el proyecto • Cambio climático • Consumo de recursos no renovables • Reciclaje • Contaminación • Políticas medioambientales • Gases líquidos • Riesgos naturales | D29: Ambiental
B34: Las empresas deben cumplir si o si la ley y esta cambia constantemente. A veces no solo aplica la ley del país donde está la empresa o el proyecto, también aplica la ley del país donde se desea estar. • Propiedad intelectual • Salud y seguridad laboral • Regulación de sectores • Leyes de protección • Salario mínimo • Licencias | D34: Legal | E34: Regulación INVIMA | F34: El sistema actualmente clasificaría como un dispositivo clase I, pudiendo llegar a clase II. posibles cambios en esta clasificación podrian impactar el proyecto | G34: x | J34: x
E35: Protección de datos clínicos | F35: El sistema manejará información sensible, por lo que debe cumplir con la Ley 1581 de 2012 en Colombia y con estándares internacionales (HIPAA, GDPR) si se escala. | G35: x | J35: x
E36: Propiedad intelectual | F36: Tanto el software como los diseños de hardware pueden protegerse para crear barreras de entrada frente a competidores | G36: x | K36: x

Sheet Ejemplo PESTEL
A1: Análisis PESTEL
A3: Factor | C3: Detalle | D3: Plazo
D4: Corto plazo (1 mes o menos) | E4: Mediano plazo (de 1 a 3 años) | F4: Largo plazo (más de 3 años) | G4: Fortalezas (F): | H4: Oportunidades (O): | I4: Debilidades (D): | J4: Amenazas (A):
A5: Político | B5: Cambio de presidente | C5: El programa de gobierno se adecua a las necesidades y expectativas de la empresa | D5: X | G5: x
B6: Las elecciones políticas de alcaldes y gobernadores | C6: Uno de los candidatos en la empresa trabajó para la competencia e inició un pleito legal por la patente del dosificador de agua | E6: X | I6: x
B7: Tratados comerciales | C7: Se planea tratado comercial con los países centroaméricanos para exportar nuestros productos | D7: X
A8: Económico | B8: Divisa | C8: La devaluación de nuestra moneda frente al dólar ha aumentado el precio de la materia prima por la fabricación de nuestros productos en un 15% | D8: X
B9: Aumento de la tasa de interés | C9: Debido al aumento de la tasa de interés la empresa no ha cumplido con su plan de inversiones, pues se requiere financiamiento de los bancos | D9: X
B10: Aumento en las exportaciones | C10: Los tratados de libre comercio del año pasado han permitido aumentar los ingresos por el concepto de exportaciones a Sudamérica | D10: X
A11: Social | B11: Aumento de la conciencia por el autocuidado | C11: Al analizar las fuentes de las ventas, un 20% indica que se han sido por autocuidado y por el conocimiento de los beneficios del agua mineral | E11: X
A12: Tecnológico | B12: Impresión 3D | C12: Puede ser posible que se realice la impresión de ciertos componentes de los filtros de agua, lo que podría optimizar los tiempos de producción y los costos | E12: X
B13: Robo de información electrónica | C13: Se perdió el 20% de información del proceso jurídico por la apertura indebida de un correo. Se establece como un riesgo no tratado ya que es la primera vez que ocurre | D13: X
A14: Ambiental | B14: Huella de carbono | C14: Se está trabajando para obtener la certificación de carbono neutro | D14: X
B15: Residuos | C15: La transformación de los residuos de producción toma tiempo y es costosa para la empresa | E15: X
A16: Legal | B16: Decreto 1072 | C16: La empresa debe dar cumplimiento al decreto 1072 que establece el SG-SST | D16: X

Sheet Estudio de Mercado-Encuesta
B2: Se desea iniciar la formulación y evaluación de un proyecto de inversión que tiene como objetivo desarrollar una aplicación móvil llamada Equilibrado+, diseñada para apoyar a personas con discapacidad en su vida diaria mediante recordatorios, reportes de caídas, rutinas de ejercicios y acompañamiento digital. Para tal fin, se realizará una investigación en la ciudad de Medellín, teniendo en cuenta que, según los registros oficiales, la población con alguna discapacidad asciende aproximadamente a 315.000 personas. a. Suponga que desea hacer la encuesta con un 95% de confianza (Z=1,96), un margen de error del 5%. ¿Cuántas encuestas debe realizar?
B5: Nivel de confianza: | C5: Z | D5: 1.96
B6: Error máximo tolerable | C6: e | D6: 0.05
B7: Poblacion | C7: N | D7: 315000 | E7: Poblacion aporx adultos mayores Medellín
B8: Desviación | C8: S | D8: 0.5
B9: Numero de Encuestas (n) | D9: =(D7*D8*D8*D5*D5)/((D6*D6*(D7-1)+D8*D8*D5*D5)) -> 383.69328
B12: De la encuesta realizada a 100 personas en la ciudad de Medellín, se vio que un porcentaje significativo mostró interés del producto para el apoyo en la vida diaria de personas con discapacidad. Las personas encuestadas indicaron que, de las funcionalidades de mayor preferencia, destacan las alertas y recordatorios (30%), el reporte de caídas (25%), las rutinas de ejercicios guiados (20%), la facilidad de uso (15%) y, finalmente, contar con un precio accesible (10%).
B15: Alertas y recordatorios | C15: 0.3 | D15: Se hicieron 100 encuestas
B16: El reporte de caídas | C16: 0.25
B17: las rutinas de ejercicios guiados (20%), la facilidad de uso (15%) y, finalmente, contar con un precio accesible (10%). | C17: 0.2 | D17: =SUM(C15:C19) -> 1
B18: la facilidad de uso | C18: 0.15
B19: Contar con un precio accesible | C19: 0.1
C22: Sesiones ejercicio | D22: Alertas activadas | E22: Descargas reporte | F22: Recordatorio diario
B23: Cantidad | C23: 5 | D23: 1 | E23: 1 | F23: 1
B24: Frecuencia | C24: por sesion | D24: Mensual | E24: Mensual | F24: Diario
B26: Población Objetivo: | C26: Población estrato 2, 3, 4, 5 y 6 de la ciudad de Medellin | E26: % Personas comprarian | F26: 0.6
B27: N: Tamaño Población | C27: =D7 -> 315000
B28: n: Tamaño Muestra | C28: =100 -> 100 | D28: 100
B30: Pregunta | C30: Enunciado | D30: Respuesta | E30: Personas | F30: %
B31: 1 | C31: Dispuesto a comprar | D31: Sí | E31: =C28*F26 -> 60 | F31: =E31/C28 -> 0.6
D32: No | E32: =+C28-E31 -> 40 | F32: =E32/C28 -> 0.4
B33: 2 | C33: Estrato socioeconómico | D33: 3 | E33: 40 | F33: =+E33/$C$28 -> 0.4
D34: 4 | E34: 12 | F34: =+E34/$C$28 -> 0.12
D35: 5 | E35: 26 | F35: =+E35/$C$28 -> 0.26
D36: 6 | E36: 22 | F36: =+E36/$C$28 -> 0.22 | G36: =C28-E37 -> 0
B37: 3 | C37: Frecuencia de compra | E37: =SUM(E33:E36) -> 100 | F37: =SUM(F33:F36) -> 1
B39: PROYECCIÓN DE DEMANDA SEGÚN ENCUESTA
B41: Población | C41: =+D7 -> 315000
B42: % Población Estrato 4,5,6 | C42: =F34+F35+F36 -> 0.6
B43: Población Estrato 4,5,6 que compra | C43: =+C41*C42 -> 189000
B45: % Población Sí compra | C45: =+F31 -> 0.6
B46: Población Estrato 4,5,6 que compra | C46: =+C43*C45 -> 113400
B49: Datos Encuesta | E49: Proyección Personas | F49: Proyección Mes | G49: Proyección Año
B50: APP | C50: 1 | E50: =C46*C50 -> 113400 | F50: =E50*1 -> 113400 | G50: =F50*12 -> 1360800
B52: AÑO | C52: Poblacion Mayor a 65 años | D52: CRECIMIENTO
B53: 2025 | C53: 315329
B54: 2026 | C54: 318597 | D54: =+C54/C53-1 -> 0.010363779 | I54: Esta es la pryeccion de suscripciones, no es igual al numero de usuarios, sino la cantidad de veces que el usuario pago en el año
B55: 2027 | C55: 322031 | D55: =+C55/C54-1 -> 0.010778507
B56: 2028 | C56: 325477 | D56: =+C56/C55-1 -> 0.010700833
B57: 2029 | C57: 329023 | D57: 0.0196
...

Sheet Est.Merca-participacion
B2: Variaciones Porcentuales
B6: Marca | C6: Año de inicio | D6: Instalaciones año inicial | E6: Instalaciones 2024 | F6: Tasa de crecimiento anual compuesta | H6: Formula de la tasas de crecimeinto anual compuesta:
B7: Thera-Trainer | C7: 2010 | D7: 50 | E7: 100000 | F7: =(E7/D7)^(1/(2024-C7))-1 -> 0.72102769
B8: One Step | C8: 2016 | D8: 50 | E8: 10000 | F8: =(E8/D8)^(1/(2024-C8))-1 -> 0.93922745

Sheet Mapa de Empatía

Sheet costos, gastos,inversiones
B3: Condiciones de mercado
B4: Costos de desarrollo tecnologico
B5: Precio de venta del producto (suscripción mensual)
B6: Capacidad servidores
B8: Precio de materiales e insumos
B9: Servidores
B10: • Políticas de crédito
B13: Inversion en activos fijos
B14: Infraestructira digital
B15: Equipod de oficina
B18: capacidad de produccion
B19: capacidad de produccion maxima
... B80: indica la necesidad de dinero de una empresa para poder cumplir con sus operaciones

Sheet Analisis tecnico
A2: ESTUDIO TÉCNICO
A4: FORMATO DE EVALUACIÓN TÉCNICA
A6: ITEM | B6: Características técnicas a evaluar | F6: Resultado
A7: 1 | B7: ¿Cuáles son las nuevas tecnologías necesarias para el desarrollo, la implementación y las operaciones del nuevo producto o proyecto? | F7: Combinación y formulación de materias primas para el cumplimiento de las especificaciones
A11: 2 | B11: ¿Se cuenta con todo el conocimiento necesario el para el desarrollo, la implementación y las operaciones del nuevo producto o proyecto? | F11: No
A15: 3 | B15: ¿Qué conocimientos no se poseen, y es factible desarrollarlos o adquirirlos durante la ejecucción y puesta en marcha del proyecto?, incluir los conocimientos que deben ser desarrollados por el personal. | F15: Estabilidad de productos y adherencia para productos que cumplan bajos ciclos de horneo
A19: 4 | B19: ¿Se cuenta con todas las herramientas necesarias el para el desarrollo, la implementación y las operaciones del nuevo producto o proyecto? | F19: Si
A23: 5 | B23: ¿Qué herramientas hacen falta, y es factible económicamente conseguirlas?, o que nuevos dispositivos deben ser desarrolados | F23: N/A
A27: 6 | B27: ¿Se cuenta con todas las habilidades necesarias para el desarrollo, la implementación y las operaciones del nuevo producto o proyecto? | F27: Si
A31: 7 | B31: ¿Qué habilidades no se poseen, y es factible económicamente desarrolladas? | F31: N/A
A35: 8 | B35: ¿Con que experiencia se cuenta en las tecnologías necesarias para el desarrollo y puesta en marcha del nuevo desarrollo? | F35: La compañía produce productos similares, adecuando la tecnología de acuerdo a las materias primas disponibles desde hace 30 años
A39: 9 | B39: ¿La reglamentación que limitantes técnicos aporta?, Estamos en capadidad de realizar el desarrollo cumpliendo con las reglamentacones existentes? | F39: La reglamentación es la misma que se tiene para los productos que se entregan actualmente y que serán reemplazados por esta nueva técnologia
A43: 10 | B43: ¿Cuáles son las innovaciones en producto y procesos que serán desarroladas con el proyecto? | F43: Capacidad de cumpliento de especificaciones a bajas condiciones de horneo
A47: 11 | B47: ¿Hay patentes que limitan el producto a desarrollar?, ¿Qué limitantes, imponen las patentes existentes?, es factible que el producto a desarrollar evite las limitaciones impuestas por las patentes? | F47: no
A51: 12 | B51: ¿Cuánto tiempo es necesario para la puesta en marcha del proyecto, teniendo en cuenta del desarrollo de las nuevas capacidades, tecnológicas y humanas? | F51: 6 meses
... A67: 16 | B67: ¿Cuál es el impacto medio ambiental del proyecto?, ¿Tienen en cuenta reducción de materiales contaminantes? | F67: Los productos deben cumplir con la reglamentación de materias primas provistas por el cliente y su casa matriz

Sheet SELECCION-LOCALIZACIÓN
A4: ESTUDIO TÉCNICO
A7: CRITERIO | B7: PESO /100 | C7: ALTERNATIVA 1 | E7: ALTERNATIVA 2
C8: CALIFICACIÓN | D8: PONDERACIÓN | E8: CALIFICACIÓN | F8: PONDERACIÓN
C9: /5 | E9: /5
A10: CLIENTES
A11: COSTOS
A12: IMPUESTOS
A13: PERSONEL DISPONIBLE
A14: ABASTECIMIENTO
A15: TOTALES | B15: SUMA=100% | D15: SUMA | F15: SUMA

Sheet FLUJO GRAMA 
A1: FLUJO GRAMA DEL PROCESO
B5: PROCESO
B17: #VALUE!
A37: ACTIVIDAD DEL PROCESO | B37: DESCRIPCION | C37: MAQUINARIA | D37: CANTIDAD | E37: VALOR | F37: VALOR TOTAL | G37: EQUIPOS | H37: VALOR | I37: CANTIDAD | J37: VALOR TOTAL | K37: MUEBLES Y ENSERES | L37: VALOR | M37: CANTIDAD | N37: VALOR TOTAL | O37: MATERIALES E INSUMOS | P37: VALOR | Q37: CANTIDAD | R37: VALOR TOTAL | S37: PERSONAL | T37: SALARIO | U37: CANTIDAD | V37: VALOR TOTAL | W37: PERMISOS -LICENCIAS | X37: VALOR | Y37: CANTIDAD | Z37: VALOR TOTAL
C38: Horno Rotatorio Panadería | D38: 1 | E38: 17500000 | F38: =+D38*E38 -> 17500000 | H38: 4000000 | I38: 1 | J38: =+H38*I38 -> 4000000 | K38: mesa | L38: 3000000 | M38: 1 | N38: =+L38*M38 -> 3000000 | O38: Papel | S38: OPERAC | T38: 2000000 | U38: 1 | V38: =+T38*U38 -> 2000000
C39: Batidoras Industriales | D39: 1 | E39: 5000000 | F39: =+D39*E39 -> 5000000
C40: Balanza | D40: 1 | E40: 600000 | F40: =+D40*E40 -> 600000
C41: Tajadora de pan | D41: 1 | E41: 10500000 | F41: =+D41*E41 -> 10500000
C42: Cortadora divisora de masa | D42: 1 | E42: 8520000 | F42: =+D42*E42 -> 8520000
C43: Amasadora | D43: 1 | E43: 8000000 | F43: =+D43*E43 -> 8000000
C44: Enfriador | D44: 1 | E44: 1800000 | F44: =+D44*E44 -> 1800000
C45: Carros escabiladeros | D45: 1 | E45: 1200000 | F45: =+D45*E45 -> 1200000
C46: Mesas (Proceso Productivo) | D46: 3 | E46: 1500000 | F46: =+D46*E46 -> 4500000
C47: Moldes, recipientes y utensilios | D47: 1 | E47: 500000 | F47: =+D47*E47 -> 500000
C48: Vitrinas Panadería y Pastelería | D48: 1 | E48: 6500000 | F48: =+D48*E48 -> 6500000
C49: Caja Registradora | D49: 1 | E49: 900000 | F49: =+D49*E49 -> 900000
C50: Computadores | D50: 4 | E50: 2000000 | F50: =+D50*E50 -> 8000000
... C52: Sillas | D52: 11 | E52: 72000 | F52: =+D52*E52 -> 792000
A53: TOTAL | C53: Sillas Gerenciales | D53: 5 | E53: 125000 | F53: =SUM(F38:F52) -> 78032000 | J53: =SUM(J38:J52) -> 4000000 | N53: =SUM(N38:N52) -> 3000000 | R53: =SUM(R38:R52) -> 0 | V53: =SUM(V38:V52) -> 2000000 | Z53: =SUM(Z38:Z52) -> 0
A56: CAPACIDAD MAXIMA PRODUCCION / PRESTACIÓN DEL SERVICIO | G56: PROYECCION DEMANDA | K56: DESFASE
B57: MAXIMO PRODUCCION / PRESTACION SERVICIO | C57: DIA | D57: SEMANA | E57: MES | F57: AÑO | G57: DIA | H57: SEMANA | I57: MES | J57: AÑO
A58: MAQUINARIA
A59: PERSONAL

Sheet inversiones
A2: Activos / Recursos Digitales | B2: Cantidad | C2: Precio Unitario [2025] | D2: VALOR TOTAL
A3: Desarrollo inicial de APP (versión básica con login, catálogo de productos y carrito de compras) | B3: 1 | C3: 12000000 | D3: 12000000
A4: Servidor Cloud / Hosting por 12 meses | B4: 1 | C4: 5000000 | D4: 5000000
A5: Software (licencias básicas: CRM, contabilidad, diseño) | B5: 1 | C5: 3000000 | D5: 3000000
A6: Pasarela de pagos (integración) | B6: 1 | C6: 500000 | D6: 500000
A7: Diseño de interfaz (branding, UX básico) | B7: 1 | C7: 2000000 | D7: 2000000
A8: Mantenimiento y soporte (primer año) | B8: 1 | C8: 2500000 | D8: 2500000
A9: Marketing digital inicial (lanzamiento y prueba de mercado) | B9: 1 | C9: 3000000 | D9: 3000000
A10: Dispositivos de prueba (celulares/tabletas para testeo) | B10: 2 | C10: 1200000 | D10: 2400000
A11: Computadores de desarrollo (ingenieros, diseño, IA) | B11: 3 | C11: 3000000 | D11: 9000000
A12: Laptops administrativas / comerciales | B12: 2 | C12: 2000000 | D12: 4000000
A13: Escritorios operativos | B13: 5 | C13: 900000 | D13: 4500000
A14: Sillas ergonómicas | B14: 5 | C14: 500000 | D14: 2500000
... A17: Tablets para validación con usuarios / EPS | B17: 10 | C17: 800000 | D17: 8000000
C18: Total Activos | D18: =SUM(D3:D17) -> 62600000

Sheet C. inversiones y costos ctables
A3: ESTUDIO TÉCNICO
A5: INVERSIONES Y COSTOS CONTABLES
A7: Item | B7: Cantidades | C7: Año 0 | F7: Costos contables
A8: DESCRIPCION | B8: CANTIDADES | C8: VALOR DE COMPRA | D8: VALOR TOTAL | E8: TIEMPO DEPRECIACION | F8: Año 1 | G8: Año 2 | H8: Año 3 | I8: Año 4 | J8: Año 5 | K8: DEPRECIACION ACUMULADA Sumatoria de los años de uso | L8: Valor en libros al final del año 5 Valor de compra (-) Depreciación acumulada | M8: Valor de venta del activo | N8: Ganancia/Pérdida en Venta de activos fijos
A9: =inversiones!A5 -> Software (licencias básicas: CRM, contabilidad, diseño) | B9: =inversiones!B5 -> 1 | C9: =inversiones!C5 -> 3000000 | D9: =inversiones!D5 -> 3000000 | E9: 5 | F9: =$D9/$E9 -> 600000 | G9: =$D9/$E9 -> 600000 | H9: =$D9/$E9 -> 600000 | I9: =$D9/$E9 -> 600000 | J9: =$D9/$E9 -> 600000 | K9: =SUM(F9:J9) -> 3000000 | L9: =D9-K9 -> 0 | M9: =L9 -> 0 | N9: =+M9-L9 -> 0
A10: =inversiones!A10 -> Dispositivos de prueba (celulares/tabletas para testeo) | B10: =inversiones!B10 -> 2 | C10: =inversiones!C10 -> 1200000 | D10: =inversiones!D10 -> 2400000 | E10: 5 | F10: =$D10/$E10 -> 480000 | G10: =$D10/$E10 -> 480000 | H10: =$D10/$E10 -> 480000 | I10: =$D10/$E10 -> 480000 | J10: =$D10/$E10 -> 480000 | K10: =SUM(F10:J10) -> 2400000 | L10: =D10-K10 -> 0 | M10: =L10 -> 0 | N10: =+M10-L10 -> 0
A11: =inversiones!A11 -> Computadores de desarrollo (ingenieros, diseño, IA) | B11: =inversiones!B11 -> 3 | C11: =inversiones!C11 -> 3000000 | D11: =inversiones!D11 -> 9000000 | E11: 5 | F11: =$D11/$E11 -> 1800000 | G11: =$D11/$E11 -> 1800000 | H11: =$D11/$E11 -> 1800000 | I11: =$D11/$E11 -> 1800000 | J11: =$D11/$E11 -> 1800000 | K11: =SUM(F11:J11) -> 9000000 | L11: =D11-K11 -> 0 | M11: =L11 -> 0 | N11: =+M11-L11 -> 0
A12: =inversiones!A12 -> Laptops administrativas / comerciales | B12: =inversiones!B12 -> 2 | C12: =inversiones!C12 -> 2000000 | D12: =inversiones!D12 -> 4000000 | E12: 5 | F12: =$D12/$E12 -> 800000 | G12: =$D12/$E12 -> 800000 | H12: =$D12/$E12 -> 800000 | I12: =$D12/$E12 -> 800000 | J12: =$D12/$E12 -> 800000 | K12: =SUM(F12:J12) -> 4000000 | L12: =D12-K12 -> 0 | M12: =L12 -> 0 | N12: =+M12-L12 -> 0
A13: =inversiones!A13 -> Escritorios operativos | B13: =inversiones!B13 -> 5 | C13: =inversiones!C13 -> 900000 | D13: =inversiones!D13 -> 4500000 | E13: 10 | F13: =$D13/$E13 -> 450000 | G13: =$D13/$E13 -> 450000 | H13: =$D13/$E13 -> 450000 | I13: =$D13/$E13 -> 450000 | J13: =$D13/$E13 -> 450000 | K13: =SUM(F13:J13) -> 2250000 | L13: =D13-K13 -> 2250000 | M13: =L13 -> 2250000 | N13: =+M13-L13 -> 0
A14: =inversiones!A14 -> Sillas ergonómicas | B14: =inversiones!B14 -> 5 | C14: =inversiones!C14 -> 500000 | D14: =inversiones!D14 -> 2500000 | E14: 10 | F14: =$D14/$E14 -> 250000 | G14: =$D14/$E14 -> 250000 | H14: =$D14/$E14 -> 250000 | I14: =$D14/$E14 -> 250000 | J14: =$D14/$E14 -> 250000 | K14: =SUM(F14:J14) -> 1250000 | L14: =D14-K14 -> 1250000 | M14: =L14 -> 1250000 | N14: =+M14-L14 -> 0
A15: =inversiones!A15 -> Router y red local | B15: =inversiones!B15 -> 1 | C15: =inversiones!C15 -> 1200000 | D15: =inversiones!D15 -> 1200000 | E15: 5 | F15: =$D15/$E15 -> 240000 | G15: =$D15/$E15 -> 240000 | H15: =$D15/$E15 -> 240000 | I15: =$D15/$E15 -> 240000 | J15: =$D15/$E15 -> 240000 | K15: =SUM(F15:J15) -> 1200000 | L15: =D15-K15 -> 0 | M15: =L15 -> 0 | N15: =+M15-L15 -> 0
A16: =inversiones!A16 -> Pantallas para monitoreo de alertas | B16: =inversiones!B16 -> 2 | C16: =inversiones!C16 -> 1500000 | D16: =inversiones!D16 -> 3000000 | E16: 5 | F16: =$D16/$E16 -> 600000 | G16: =$D16/$E16 -> 600000 | H16: =$D16/$E16 -> 600000 | I16: =$D16/$E16 -> 600000 | J16: =$D16/$E16 -> 600000 | K16: =SUM(F16:J16) -> 3000000 | L16: =D16-K16 -> 0 | M16: =L16 -> 0 | N16: =+M16-L16 -> 0
A17: =inversiones!A17 -> Tablets para validación con usuarios / EPS | B17: =inversiones!B17 -> 10 | C17: =inversiones!C17 -> 800000 | D17: =inversiones!D17 -> 8000000 | E17: 5 | F17: =$D17/$E17 -> 1600000 | G17: =$D17/$E17 -> 1600000 | H17: =$D17/$E17 -> 1600000 | I17: =$D17/$E17 -> 1600000 | J17: =$D17/$E17 -> 1600000 | K17: =SUM(F17:J17) -> 8000000 | L17: =D17-K17 -> 0 | M17: =L17 -> 0 | N17: =+M17-L17 -> 0
C18: =inversiones!C18 -> Total Activos | D18: =SUM(D9:D17) -> 37600000 | F18: =SUM(F9:F17) -> 6820000 | G18: =SUM(G9:G17) -> 6820000 | H18: =SUM(H9:H17) -> 6820000 | I18: =SUM(I9:I17) -> 6820000 | J18: =SUM(J9:J17) -> 6820000 | K18: Valor en libros | L18: =SUM(L9:L17) -> 3500000
D19: =inversiones!D18 -> 62600000
A21: DEPRECIACION = (VALOR DEL ACTIVO -VALOR SALVAMENTO)/NRO AÑOS A DEPRECIAR
A22: DEPRECIACION ACUMULADA= VALOR DEPRECIACION DEL AÑO ACTUAL + DEPRECIACION ACUMULADA AÑO ANTERIOR
A23: VALOR LIBROS= VALOR DEL ACTIVO _ DEPRECIACION ACUMULADA
A24: GANACIA O PERDIDA = VALOR EN LIBROS - VALOR VENTA

Sheet Identificación de costos
B2: ESTUDIO TECNICO-ESTUDIO DE COSTOS
B4: Costos Variables
B6: Equilibrio+
B7: Materia Prima (Costo DIRECTO) | C7: Requerimiento | D7: Costo 2025
B8: Pasarela de pagos | C8: configuracion + integracion (comisión por pago) | D8: 30000
B11: Materia Prima (Costo Indirecto) | C11: Requerimiento | D11: Costo 2025
B12: Licencia App Store / Google Play | C12: Anual (prorrateado mensual) | D12: 90000
B13: Marketing digital inicial | C13: Campana minima redes sociales | D13: 500000
B14: Soporte tecnico (horas freelance) | C14: 20 hrs mes | D14: 400000 | E14: =SUM(D12:D14) -> 990000
B17: COSTO VARIABLE UNITARIO | D17: =SUM(D8:D8)+ SUM(D12:D14) -> 1020000
I19: =+SUM('[1]2.A. Estudio Inversiones'!G7:G13) -> 51920000
B20: Costos Laborales de produccion ( desarrollo + soporte tecnico)
I21: proyeccion suscripciones
B22: Empleado | C22: # Empleados | D22: Salario Mensual 2024 | E22: Carga prestacional | F22: Salario Mensual con Factor Prestacional 2025 | G22: Costo ANUAL Nómina 2025 | H22: Observacion | I22: 10000
B23: Jefe de tecnologia (CTO) | C23: 1 | D23: ='Plantilla Nomina'!C8 -> 10000000 | E23: ='Plantilla Nomina'!O8 -> 5093866.7 | F23: =D23+E23 -> 15093867 | G23: =+F23*12 -> 181126400 | I23: =G23/$I$22 -> 18112.64
B24: Desarrollador Full-Stack | C24: 2 | D24: ='Plantilla Nomina'!C9 -> 4500000 | E24: ='Plantilla Nomina'!O9 -> 2292240 | F24: =D24+E24 -> 6792240 | G24: =+F24*12 -> 81506880 | I24: =G24/$I$22 -> 8150.688
B25: Disenyador UX/UI | C25: 1 | D25: 2400000 | E25: 1456028 | F25: =D25+E25 -> 3856028 | G25: =+F25*12 -> 46272336 | I25: =G25/$I$22 -> 4627.2336
B26: Soporte tecnico | C26: 1 | D26: 1750000 | E26: 1124926.7 | F26: =D26+E26 -> 2874926.7 | G26: =+F26*12 -> 34499120 | I26: =G26/$I$22 -> 3449.912
B27: TOTAL COSTO MANO DE OBRA PRODUCCION | G27: =SUM(G23:G26) -> 343404736 | I27: =SUM(I23:I26) -> 34340.474
B29: Gastos Laborales administracion
B31: Empleado | C31: # Empleados | D31: Salario Mensual 2024 | E31: Carga prestacional | F31: Salario Mensual con Factor Prestacional 2025 | G31: Costo ANUAL Nómina 2025
B32: Gerente General | C32: 1 | D32: 4000000 | E32: 2037546.7 | F32: =D32+E32 -> 6037546.7 | G32: =+F32*12 -> 72450560
B33: Coordinador de Marketing | C33: 1 | D33: 2500000 | E33: 1506966.7 | F33: =D33+E33 -> 4006966.7 | G33: =+F33*12 -> 48083600
B34: Community Manager | C34: 1 | D34: 1800000 | E34: 1150396 | F34: =D34+E34 -> 2950396 | G34: =+F34*12 -> 35404752
B35: Contador | C35: 1 | D35: 2000000 | E35: 1252273.3 | F35: =D35+E35 -> 3252273.3 | G35: =+F35*12 -> 39027280
B36: Personal de Aseo Administrativo | C36: 1 | D36: 1423500 | E36: 958611.92 | F36: =D36+E36 -> 2382111.9 | G36: =+F36*12 -> 28585343
B37: TOTAL GASTOS LABORALES ADMINISTRATIVO | G37: =SUM(G32:G36) -> 2.2355154e+08
B40: GASTOS DE OPERACION FIJOS ANUALES
B42: Rubro | C42: Periodicidad | E42: Periodicidad/Año | F42: Costo POR PERIODO 2025 | H42: Costo ANUAL 2025 | I42: PERIODICIDAD
B43: Arrendamiento | C43: Mensual | E43: 12 | F43: 2000000 | H43: =+F43*E43 -> 24000000 | I43: Mensual | J43: CFT
B44: Servicios Públicos | C44: Mensual | E44: 12 | F44: 600000 | H44: =+F44*E44 -> 7200000 | I44: Mensual | J44: CFT
B45: Hosting y servidores cloud (AWS) | C45: Mensual | E45: 12 | F45: 350000 | H45: =+F45*E45 -> 4200000 | I45: Trimestral | J45: CFT
B46: Mantenimiento Equipos (laptops, tablets) | C46: Trimestral | E46: 4 | F46: 800000 | H46: =+F46*E46 -> 3200000 | I46: Mensual | J46: CFT
B47: Plan software administrativo (CRM, Contabilidad, gestion de usuarios) | C47: Mensual | E47: 12 | F47: 300000 | H47: =+F47*E47 -> 3600000
B48: Seguros | C48: Anual | E48: 1 | F48: 5000000 | H48: =+F48*E48 -> 5000000
B49: TOTAL GASTOS DE OPERACIÓN FIJOS | H49: =SUM(H43:H48) -> 47200000
B57: Costo de Producción-Costo variable | E57: Equilibrado+
C58: Materia prima directa (MD) | E58: =D8 -> 30000
C59: costos indiractod de fabricacion CIF | E59: =E14 -> 990000
C60: Mano de obra Directa (MOD) | E60: =+I27 -> 34340.474
...

Sheet Punto de equilibrio
A2: ESTUDIO TÉCNICO
A4: Punto de equilibrio
B5: UNIDADES VENTA PROYECTADA
A6: Equilibrado+ | B6: =+'Identificación de costos'!D70 -> 10000
C8: participacion en la venta
A9: gato totale total | C9: Equilibrado+
C10: =+'Identificación de costos'!D72 -> 1
B11: =+'Identificación de costos'!D65 -> 47200000 | C11: =+B11*C10 -> 47200000
A12: Depreciacion Anual | B12: ='C. inversiones y costos ctables'!F19 -> 0 | C12: =+B12*'Identificación de costos'!D72 -> 0
B14: Equilibrado+
A15: Costos totales | B15: =+C11 -> 47200000
A16: Depreciación | B16: =+C12 -> 0
A17: PVP | B17: =+'Identificación de costos'!D88 -> 1091814.9
A18: CVU | B18: =+'Identificación de costos'!D85 -> 1054340.5 | E18: =+B17-B18 -> 37474.448
A19: Q* | B19: =+(B15+B16)/(B17-B18) -> 1259.5249
A21: PROYECCION VENTAS | B21: =+'Identificación de costos'!I22 -> 10000
