Workbook

Sheet Análisis Financiero
B2: Cálculo del WACC | F2: Sensibilidad del WACC | M2: Fuente: https://es.investing.com/rates-bonds/colombia-10-year-bond-yield
B3: Insumos y estructura de capital | F3: Escenario | G3: Peso Deuda (Wd) | H3: Peso Patrimonio (We) | I3: Costo de deuda (Kd) | J3: Costo Capital (ke) | K3: WACC
B4: Deuda | C4: D | D4: ='Flujo de Caja'!C30 -> 78563501 | F4: 1 | G4: 0 | H4: 1 | I4: ='Datos Bancolombia'!$B$18 -> 0.15899 | J4: ='Datos Bancolombia'!$B$16 -> 0.14287894 | K4: =H4*J4+G4*I4 -> 0.14287894
B5: Patrimonio | C5: E | D5: ='Flujo de Caja'!C31 -> 52375668 | F5: 2 | G5: 0.05 | H5: 0.95 | I5: ='Datos Bancolombia'!$B$18 -> 0.15899 | J5: ='Datos Bancolombia'!$B$16 -> 0.14287894 | K5: =H5*J5+G5*I5 -> 0.14368449 | M5: Fuente: https://repository.unad.edu.co/bitstream/handle/10596/66934/mlbejaranod.pdf (página 69)
B6: Valor total | C6: V = D + E | D6: =D4+D5 -> 1.3093917e+08 | F6: 3 | G6: 0.1 | H6: 0.9 | I6: ='Datos Bancolombia'!$B$18 -> 0.15899 | J6: ='Datos Bancolombia'!$B$16 -> 0.14287894 | K6: =H6*J6+G6*I6 -> 0.14449005
B7: Peso deuda | C7: w_D = D/V | D7: =D4/D6 -> 0.6 | F7: 4 | G7: 0.15 | H7: 0.85 | I7: ='Datos Bancolombia'!$B$18 -> 0.15899 | J7: ='Datos Bancolombia'!$B$16 -> 0.14287894 | K7: =H7*J7+G7*I7 -> 0.1452956
B8: Peso patrimonio | C8: w_E = E/V | D8: =D5/D6 -> 0.4 | F8: 5 | G8: 0.2 | H8: 0.8 | I8: ='Datos Bancolombia'!$B$18 -> 0.15899 | J8: ='Datos Bancolombia'!$B$16 -> 0.14287894 | K8: =H8*J8+G8*I8 -> 0.14610115
B9: Tasa interés deuda nominal | C9: k_d,pre | D9: 0.25 | F9: 6 | G9: 0.25 | H9: 0.75 | I9: ='Datos Bancolombia'!$B$18 -> 0.15899 | J9: ='Datos Bancolombia'!$B$16 -> 0.14287894 | K9: =H9*J9+G9*I9 -> 0.1469067
B10: Tasa de impuesto | C10: T | D10: 0.35 | F10: 7 | G10: 0.3 | H10: 0.7 | I10: ='Datos Bancolombia'!$B$18 -> 0.15899 | J10: ='Datos Bancolombia'!$B$16 -> 0.14287894 | K10: =H10*J10+G10*I10 -> 0.14771226
B11: Costo deuda neto | C11: k_d,post = k_d,pre*(1-T) | D11: =D9*(1-D10) -> 0.1625 | F11: 8 | G11: 0.35 | H11: 0.65 | I11: ='Datos Bancolombia'!$B$18 -> 0.15899 | J11: ='Datos Bancolombia'!$B$16 -> 0.14287894 | K11: =H11*J11+G11*I11 -> 0.14851781
B12: Costo capital propio | C12: k_e | D12: 0.3 | F12: 9 | G12: 0.4 | H12: 0.6 | I12: ='Datos Bancolombia'!$B$18 -> 0.15899 | J12: ='Datos Bancolombia'!$B$16 -> 0.14287894 | K12: =H12*J12+G12*I12 -> 0.14932336
B13: WACC = w_E*k_e + w_D*k_d,post | D13: =D8*D12 + D7*D11 -> 0.2175 | F13: 10 | G13: 0.45 | H13: 0.55 | I13: ='Datos Bancolombia'!$B$18 -> 0.15899 | J13: ='Datos Bancolombia'!$B$16 -> 0.14287894 | K13: =H13*J13+G13*I13 -> 0.15012892
F14: 11 | G14: 0.5 | H14: 0.5 | I14: ='Datos Bancolombia'!$B$18 -> 0.15899 | J14: ='Datos Bancolombia'!$B$16 -> 0.14287894 | K14: =H14*J14+G14*I14 -> 0.15093447
B15: CAPM (opcional para estimar k_e) | F15: 12 | G15: 0.55 | H15: 0.45 | I15: ='Datos Bancolombia'!$B$18 -> 0.15899 | J15: ='Datos Bancolombia'!$B$16 -> 0.14287894 | K15: =H15*J15+G15*I15 -> 0.15174002
B16: Tasa libre de riesgo | C16: r_f | D16: 0.11393 | F16: 13 | G16: 0.6 | H16: 0.4 | I16: ='Datos Bancolombia'!$B$18 -> 0.15899 | J16: ='Datos Bancolombia'!$B$16 -> 0.14287894 | K16: =H16*J16+G16*I16 -> 0.15254558
B17: Prima de riesgo de mercado | C17: ERP | D17: 0.08 | F17: 14 | G17: 0.65 | H17: 0.35 | I17: ='Datos Bancolombia'!$B$18 -> 0.15899 | J17: ='Datos Bancolombia'!$B$16 -> 0.14287894 | K17: =H17*J17+G17*I17 -> 0.15335113
B18: Prima de riesgo país | C18: CRP | D18: 0.03 | F18: 15 | G18: 0.7 | H18: 0.3 | I18: ='Datos Bancolombia'!$B$18 -> 0.15899 | J18: ='Datos Bancolombia'!$B$16 -> 0.14287894 | K18: =H18*J18+G18*I18 -> 0.15415668
B19: Beta sin apalancar | C19: β_U | D19: 1.1 | F19: 16 | G19: 0.75 | H19: 0.25 | I19: ='Datos Bancolombia'!$B$18 -> 0.15899 | J19: ='Datos Bancolombia'!$B$16 -> 0.14287894 | K19: =H19*J19+G19*I19 -> 0.15496223
B20: Relación D/E | C20: D/E | D20: =D4/D5 -> 1.5 | F20: 17 | G20: 0.8 | H20: 0.2 | I20: ='Datos Bancolombia'!$B$18 -> 0.15899 | J20: ='Datos Bancolombia'!$B$16 -> 0.14287894 | K20: =H20*J20+G20*I20 -> 0.15576779
B21: β apalancada | C21: β_L = β_U*(1+(1-T)*D/E) | D21: =D19*(1+(1-D10)*D20) -> 2.1725 | F21: 18 | G21: 0.85 | H21: 0.15 | I21: ='Datos Bancolombia'!$B$18 -> 0.15899 | J21: ='Datos Bancolombia'!$B$16 -> 0.14287894 | K21: =H21*J21+G21*I21 -> 0.15657334
B22: k_e (CAPM) | C22: k_e (CAPM) = r_f + β_L*ERP + CRP | D22: =D16 + D21*D17 + D18 -> 0.31773 | F22: 19 | G22: 0.9 | H22: 0.1 | I22: ='Datos Bancolombia'!$B$18 -> 0.15899 | J22: ='Datos Bancolombia'!$B$16 -> 0.14287894 | K22: =H22*J22+G22*I22 -> 0.15737889
B23: k_e seleccionado (usar TIO=30% o CAPM) | D23: ='Flujo de Caja'!C97 -> 0.30562489 | F23: 20 | G23: 0.95 | H23: 0.05 | I23: ='Datos Bancolombia'!$B$18 -> 0.15899 | J23: ='Datos Bancolombia'!$B$16 -> 0.14287894 | K23: =H23*J23+G23*I23 -> 0.15818445
F24: 21 | G24: 1 | H24: 0 | I24: ='Datos Bancolombia'!$B$18 -> 0.15899 | J24: ='Datos Bancolombia'!$B$16 -> 0.14287894 | K24: =H24*J24+G24*I24 -> 0.15899
B25: Chequeo VPN con WACC usando FCL del proyecto
B26: Año | C26: Flujo de caja libre (FCL) | D26: Valor presente
B27: 0 | C27: -130939169 | D27: =C27 -> -130939169
B28: 1 | C28: 43752455 | D28: =C28/(1+$D$13)^1 -> 35936308
B29: 2 | C29: 54985854 | D29: =C29/(1+$D$13)^2 -> 37094800
B30: 3 | C30: 68076597 | D30: =C30/(1+$D$13)^3 -> 37721671 | H30: TIR (FLUJO DE CAJA LIBRE) | I30: TIR (VALOR PRESENTE )
B31: 4 | C31: 83248039 | D31: =C31/(1+$D$13)^4 -> 37887690 | H31: =IRR(C27:C32) -> 0.3790623 | I31: =IRR(D27:D32) -> 0.13270004
B32: 5 | C32: 106380538 | D32: =C32/(1+$D$13)^5 -> 39766497
B33: VPN (suma de valores presentes) | D33: =SUM(D27:D32) -> 57467798
B34: Comparación de VPNs | D34: ='Flujo de Caja'!C70-D33 -> 0.71265618 | H34: TIR | I34: MAYOR | J34: WACC | K34: VIABLE
H35: TIR | I35: MENOR | J35: WACC | K35: NO VIABLE
B36: INDICADORES FINANCIEROS COMPLEMENTARIOS
B38: INDICADORES DEL PROYECTO
B39: WACC (Costo de capital) | C39: =D13 -> 0.2175 | D39: % | E39: Tasa de descuento del proyecto
B40: VPN (Valor Presente Neto) | C40: ='Flujo de Caja'!C70 -> 57467798 | D40: COP | E40: Valor presente de flujos futuros
B41: TIR (Tasa Interna Retorno) | C41: ='Flujo de Caja'!C71 -> 0.37906231 | D41: % | E41: Rentabilidad del proyecto
B42: Margen TIR - WACC | C42: ='Flujo de Caja'!C72 -> 0.16156231 | D42: % | E42: Rentabilidad excedente
...

Sheet Flujo de Caja
B2: 7. ESTUDIO FINANCIERO
B4: 7.1 INGRESOS, COSTOS Y GASTOS PROYECTADOS
C5: IPC PROM | D5: ='Indicadores Macro'!D11 -> 0.064383333 | E5: IPP PROM | F5: ='Indicadores Macro'!H11 -> 0.07
B6: Concepto | C6: Año 1 | D6: Año 2 | E6: Año 3 | F6: Año 4 | G6: Año 5
B7: Nivel de producción año | C7: =Tamaño!C10 -> 3081.6 | D7: =Tamaño!C11 -> 3297.312 | E7: =Tamaño!C12 -> 3528.1238 | F7: =Tamaño!C13 -> 3775.0925 | G7: =Tamaño!C14 -> 4039.349
B8: Capacidad efectiva año | C8: 0.6 | D8: =C8+10% -> 0.7 | E8: =D8+10% -> 0.8 | F8: =E8+10% -> 0.9 | G8: =F8+10% -> 1
B9: Nivel de producción efectiva año | C9: =C7*C8 -> 1848.96 | D9: =D7*D8 -> 2308.1184 | E9: =E7*E8 -> 2822.4991 | F9: =F7*F8 -> 3397.5833 | G9: =G7*G8 -> 4039.349
B10: Precio de venta del proyecto | C10: ='Precio Proy'!F6 -> 215635.87 | D10: =C10*(1+$D5) -> 229519.23 | E10: =D10*(1+$D5) -> 244296.44 | F10: =E10*(1+$D5) -> 260025.06 | G10: =F10*(1+$D5) -> 276766.34
B11: Costos de producción unidad | C11: =Costos!F19 -> 106104.75 | D11: =C11*(1+$F5) -> 113532.08 | E11: =D11*(1+$F5) -> 121479.33 | F11: =E11*(1+$F5) -> 129982.88 | G11: =F11*(1+$F5) -> 139081.68
B12: Gastos de administración y venta unidad | C12: =Gastos!F22 -> 77185.743 | D12: =C12*(1+$F5) -> 82588.745 | E12: =D12*(1+$F5) -> 88369.957 | F12: =E12*(1+$F5) -> 94555.854 | G12: =F12*(1+$F5) -> 101174.76
B13: Total costos y gastos unitarios | C13: =C11+C12 -> 183290.49 | D13: =D11+D12 -> 196120.83 | E13: =E11+E12 -> 209849.29 | F13: =F11+F12 -> 224538.74 | G13: =G11+G12 -> 240256.45
B14: Ingresos proyectados por año | C14: =C9*C10 -> 3.9870211e+08 | D14: =D9*D10 -> 5.2975756e+08 | E14: =E9*E10 -> 6.8952649e+08 | F14: =F9*F10 -> 8.834568e+08 | G14: =G9*G10 -> 1.1179558e+09
B15: Costos proyectados por año | C15: =C9*C11 -> 1.9618344e+08 | D15: =D9*D11 -> 2.6204549e+08 | E15: =E9*E11 -> 3.4287529e+08 | F15: =F9*F11 -> 4.4162766e+08 | G15: =G9*G11 -> 5.6179945e+08
B16: Gastos proyectados por año | C16: =C9*C12 -> 1.4271335e+08 | D16: =D9*D12 -> 1.906246e+08 | E16: =E9*E12 -> 2.4942412e+08 | F16: =F9*F12 -> 3.2126139e+08 | G16: =G9*G12 -> 4.0868018e+08
B18: 7.2 PRESUPUESTO DE INVERSIÓN
B20: Concepto | C20: Valor
B21: Capital de trabajo | C21: =(C16)*1.5/12 -> 17839169
B22: Inventario | C22: 0
B23: Equipos de planta y oficina | C23: =Costos!E25+Gastos!E28 -> 86800000
B24: Adecuaciones y gastos legales | C24: 26300000
B25: total inversión | C25: =SUM(C21:C24) -> 1.3093917e+08
B27: 7.3 FUENTES DE FINANCIACIÓN
B29: Recursos | C29: Valor | D29: Participación
B30: Recursos de créditos | C30: =$C$25*D30 -> 78563501 | D30: 0.6
B31: Recursos de socios | C31: =$C$25*D31 -> 52375668 | D31: 0.4
B32: Total fuentes | C32: =SUM(C30:C31) -> 1.3093917e+08 | D32: =SUM(D30:D31) -> 1
B33: Tasa de interés del crédito | C33: 0.25 | D33: EA
B34: Tasa de interés del inversionista (TIO) | C34: 0.3 | D34: EA
B35: Tasa del impuesto de renta (escudo fiscal) | C35: 0.35 | D35: EA
B36: Monto | C36: =C30 -> 78563501
B37: Plazo | C37: 5 | D37: años
B38: Cuota | C38: =PMT(C33,C37,-C36) -> 29213582
B39: Concepto | C39: Año 0 | D39: Año 1 | E39: Año 2 | F39: Año 3 | G39: Año 4 | H39: Año 5
B40: Cuota | D40: =$C$38 -> 29213582 | E40: =$C$38 -> 29213582 | F40: =$C$38 -> 29213582 | G40: =$C$38 -> 29213582 | H40: =$C$38 -> 29213582
B41: Interés | D41: =C43*$C$33 -> 19640875 | E41: =D43*$C$33 -> 17247699 | F41: =E43*$C$33 -> 14256228 | G41: =F43*$C$33 -> 10516889 | H41: =G43*$C$33 -> 5842716.4
B42: Abono | D42: =D40-D41 -> 9572706.5 | E42: =E40-E41 -> 11965883 | F42: =F40-F41 -> 14957354 | G42: =G40-G41 -> 18696692 | H42: =H40-H41 -> 23370865
B43: Saldo | C43: =C36 -> 78563501 | D43: =C43-D42 -> 68990795 | E43: =D43-E42 -> 57024912 | F43: =E43-F42 -> 42067558 | G43: =F43-G42 -> 23370865 | H43: =G43-H42 -> 0
B44: Fuente | C44: Monto | D44: Participación | E44: Costo sin escudo fiscal | F44: Costo con escudo fiscal | G44: Costo de capital
B45: =B30 -> Recursos de créditos | C45: =C30 -> 78563501 | D45: =C45/$C$47 -> 0.6 | E45: =C33 -> 0.25 | F45: =E45*(1-C35) -> 0.1625 | G45: =D45*F45 -> 0.0975
B46: =B31 -> Recursos de socios | C46: =C31 -> 52375668 | D46: =C46/$C$47 -> 0.4 | E46: =C34 -> 0.3 | F46: =E46 -> 0.3 | G46: =D46*F46 -> 0.12
...

Sheet Datos Bancolombia
A1: Impuesto corporativo | B1: T | C1: 0.35 | D1: https://taxsummaries.pwc.com/colombia/corporate/taxes-on-corporate-income
A2: Renta fija TES 10 anos | B2: TES | C2: 0.116 | D2: https://www.investing.com/rates-bonds/colombia-10-year-bond-yield
A3: ERP 2024 COL | B3: ERP | C3: 0.0687 | D3: EXCEL
A4: CRP COL | B4: CRP | C4: 0.0254 | D4: EXCEL
A5: BETA NO APALANCADA | B5: BETHA | C5: 0.0109 | D5: https://pages.stern.nyu.edu/~adamodar/New_Home_Page/datafile/Betas.html
D6: https://www.superfinanciera.gov.co/powerbi/reportes/533/483
A9: Relacion deuda/patrimonio | B9: D/E | C9: ='Análisis Financiero'!D4/'Análisis Financiero'!D5 -> 1.5 | D9: Analisis financiero
A10: En Colombia la tasa nominal del impuesto sobre la renta para personas jurídicas es del 35 % para el año gravable 2025. | B10: impuesto corporativo | C10: 0.35 | D10: https://actualicese.com/tarifa-general-del-impuesto-de-renta-2025-para-personas-juridicas/?srsltid=AfmBOoocjb24t_woY6WSveRQe_wP5glW6kbiXNnaLv8yNf7dhqO51T-P&utm
A11: Kd ,pre = Tasa interes nominal cobrada por los bancos Según la Superintendencia Financiera de Colombia, la tasa de interés bancario corriente (IBC) para crédito de consumo y ordinario (octubre 2025) está en torno a 16,24 % efectivo anual. Los bancos como Bancolombia, Davivienda o BBVA aplican tasas comerciales entre 15 % y 18 % EA para empresas con riesgo medio. | B11: Kd pre Efectivo annual | C11: 0.1642 | D11: https://www.superfinanciera.gov.co/publicaciones/10115702/superfinanciera-certifica-el-interes-bancario-corriente/
A12: bancolombia | B12: Kd efectivo anaual | C12: 0.2446 | G12: =84/12 -> 7 | H12: =5*12 -> 60
A15: Beta apalancada | B15: =C5*(1+(1-C10)*C9) -> 0.0215275
A16: Ke | B16: =C2+B15*C3+C4 -> 0.14287894
A17: Kd | B17: =C12 -> 0.2446
A18: Kd (post ) | B18: =B17*(1-C10) -> 0.15899

Sheet RBC y BAUE
B2: RELACIÓN BENEFICIO-COSTO (RBC) Y BAUE
B5: 1. RELACIÓN BENEFICIO-COSTO (RBC)
B7: Concepto | C7: Fórmula | D7: Valor | E7: Interpretación
B9: Valor Presente Ingresos (VPI) | C9: NPV(WACC,Ingresos) | D9: =NPV('Análisis Financiero'!D13,'Flujo de Caja'!D52:H52) -> 1.8869188e+09 | E9: VP de todos los ingresos
B10: Valor Presente Egresos (VPE) | C10: Inv + NPV(WACC,Egresos) | D10: ='Flujo de Caja'!C67+NPV('Análisis Financiero'!D13,'Flujo de Caja'!D55:H55)+NPV('Análisis Financiero'!D13,'Flujo de Caja'!D56:H56) -> 1.7528561e+09 | E10: VP de egresos + inversión
B12: RBC = VPI / VPE | C12: VPI/VPE | D12: =D9/D10 -> 1.0764824 | E12: Beneficio por cada peso invertido
B14: Interpretación:
B15: Si RBC > 1 | C15: → | D15: Proyecto VIABLE | E15: Genera más beneficios que costos
B16: Si RBC = 1 | C16: → | D16: Punto de equilibrio | E16: Beneficios = Costos
B17: Si RBC < 1 | C17: → | D17: NO VIABLE | E17: Genera pérdidas
B20: 2. BENEFICIO ANUAL UNIFORME EQUIVALENTE (BAUE)
B22: Concepto | C22: Fórmula | D22: Valor | E22: Interpretación
B24: VPN del Proyecto | C24: VPN | D24: ='Flujo de Caja'!C70 -> 57467798 | E24: Del flujo de caja libre
B25: WACC | C25: Tasa | D25: ='Análisis Financiero'!D13 -> 0.2175 | E25: Tasa de descuento
B26: Horizonte (n) | C26: Años | D26: 5 | E26: Vida del proyecto
B28: BAUE = -PMT(WACC,n,VPN) | C28: -PMT | D28: =-PMT(D24,D25,D23) -> 0 | E28: Beneficio anual equivalente
B30: Interpretación:
B31: BAUE > 0 | C31: → | D31: Proyecto VIABLE | E31: Genera beneficios anuales
B32: BAUE = 0 | C32: → | D32: Punto de equilibrio | E32: Sin beneficios ni pérdidas
B33: BAUE < 0 | C33: → | D33: NO VIABLE | E33: Genera pérdidas anuales
B35: Nota: BAUE permite comparar proyectos con diferentes horizontes temporales

Sheet Indicadores Macro
B2: INDICADORES MACROECONÓMICOS
B4: Año | C4: Período | D4: IPC Anual | F4: Año | G4: Período | H4: IPP Anual | J4: Año | K4: Período | L4: PIB Anual | N4: Año | O4: Período | P4: TIB Anual
B5: 2019 | C5: 1 | D5: 0.038 | F5: 2019 | G5: 1 | H5: 0.023 | J5: 2019 | K5: 1 | N5: 2019 | O5: 1 | P5: 0.0425
B6: 2020 | C6: 2 | D6: 0.0161 | F6: 2020 | G6: 2 | H6: 0.017 | J6: 2020 | K6: 2 | L6: -0.055 | N6: 2020 | O6: 2 | P6: 0.0275
B7: 2021 | C7: 3 | D7: 0.0562 | F7: 2021 | G7: 3 | H7: 0.159 | J7: 2021 | K7: 3 | L7: 0.173 | N7: 2021 | O7: 3 | P7: 0.0175
B8: 2022 | C8: 4 | D8: 0.1312 | F8: 2022 | G8: 4 | H8: 0.216 | J8: 2022 | K8: 4 | L8: 0.171 | N8: 2022 | O8: 4 | P8: 0.0775
B9: 2023 | C9: 5 | D9: 0.0928 | F9: 2023 | G9: 5 | H9: -0.029 | I9: 0.0721 | J9: 2023 | K9: 5 | L9: 0.077 | N9: 2023 | O9: 5 | P9: 0.1275
B10: 2024 | C10: 6 | D10: 0.052 | F10: 2024 | G10: 6 | H10: 0.034 | J10: 2024 | K10: 6 | L10: 0.06 | N10: 2024 | O10: 6 | P10: 0.1025
C11: PROM | D11: =AVERAGE(D5:D10) -> 0.064383333 | G11: PROM | H11: =AVERAGE(H5:H10) -> 0.07 | K11: PROM | L11: =AVERAGE(L5:L10) -> 0.0852 | O11: PROM | P11: =AVERAGE(P5:P10) -> 0.065833333

Sheet Demanda
B2: PROYECCIÓN DE DEMANDA
B4: Producto | C4: App salud | D4: Dato | E4: Fuente
B5: Población objetivo | C5: Estudiantes de la universidad Eafit | D5: 12000 | E5: Datos otorgados por la Universidad
B6: Filtro 1 | C6: % diispuestos a comprar | D6: 0.646 | E6: Encuesta de segmentacion
B7: Filtro 2 | C7: % estudiantes que respondieron "Tal vez", teniendo en cuenta que solo el 50% adoptaria la app. | D7: =24.6%*50% -> 0.123 | E7: Encuesta de segmentacion
B8: Filtro 3 | C8: Factor de corrección por intención vs. acción real, (estándar para aplicaciones móviles) | D8: 0.7 | E8: Pruebas UX
B9: Total demanda | D9: =D5*(D6+D7)*D8 -> 6459.6 | H9: segmentación de demanda
B10: Período | C10: Año | D10: PROM IPC | E10: Cantidad | H10: Año | I10: Periodo | J10: Demanda total | K10: Usuario versión gratuita | L10: usuario versión premium | M10: =58.3%+16.7% -> 0.75 | N10: =40%*75% -> 0.3
B11: Base | C11: 2025 | E11: =D9 -> 6459.6 | H11: 2025 | I11: 0 | J11: =E11 -> 6459.6 | K11: =J11*48.5% -> 3132.906 | L11: =J11*51.5% -> 3326.694
B12: 1 | C12: 2026 | D12: ='Indicadores Macro'!$D$11 -> 0.064383333 | E12: =E11*(1+D12) -> 6875.4906 | H12: 2026 | I12: 1 | J12: =E12 -> 6875.4906 | K12: =J12*48.5% -> 3334.6129 | L12: =J12*51.5% -> 3540.8776
B13: 2 | C13: 2027 | D13: ='Indicadores Macro'!$D$11 -> 0.064383333 | E13: =E12*(1+D13) -> 7318.1576 | H13: 2027 | I13: 2 | J13: =E13 -> 7318.1576 | K13: =J13*48.5% -> 3549.3064 | L13: =J13*51.5% -> 3768.8512
B14: 3 | C14: 2028 | D14: ='Indicadores Macro'!$D$11 -> 0.064383333 | E14: =E13*(1+D14) -> 7789.325 | H14: 2028 | I14: 3 | J14: =E14 -> 7789.325 | K14: =J14*48.5% -> 3777.8226 | L14: =J14*51.5% -> 4011.5024 | O14: =100-51.5 -> 48.5
B15: 4 | C15: 2029 | D15: ='Indicadores Macro'!$D$11 -> 0.064383333 | E15: =E14*(1+D15) -> 8290.8277 | H15: 2029 | I15: 4 | J15: =E15 -> 8290.8277 | K15: =J15*48.5% -> 4021.0514 | L15: =J15*51.5% -> 4269.7762
B16: 5 | C16: 2030 | D16: ='Indicadores Macro'!$D$11 -> 0.064383333 | E16: =E15*(1+D16) -> 8824.6188 | F16: =E16/D5 -> 0.7353849 | H16: 2030 | I16: 5 | J16: =E16 -> 8824.6188 | K16: =J16*48.5% -> 4279.9401 | L16: =J16*51.5% -> 4544.6787
B19: FUNCIÓN DE LA DEMANDA | C19: P = MQ + C | D19: PROM IPC | E19: =D12 -> 0.064383333
B22: P1 | C22: 53000 | D22: Q1 | E22: =L11 -> 3326.694
B23: P2 | C23: =C22/(1+E19) -> 49794.09 | D23: Q2 | E23: =L12 -> 3540.8776
C25: M | D25: C | E25: Q | F25: P
B26: Año | C26: Pendiente | D26: Intercepto | E26: Cantidad | F26: Precio
B27: =C12 -> 2026 | C27: =SLOPE($C$22:$C$23,$E$22:$E$23) -> -14.96804 | D27: =INTERCEPT($C$22:$C$23,$E$22:$E$23) -> 102794.09 | E27: =L12 -> 3540.8776 | F27: =C27*E27+D27 -> 49794.09
B28: =C13 -> 2027 | C28: =SLOPE($C$22:$C$23,$E$22:$E$23) -> -14.96804 | D28: =INTERCEPT($C$22:$C$23,$E$22:$E$23) -> 102794.09 | E28: =L13 -> 3768.8512 | F28: =C28*E28+D28 -> 46381.774
B29: =C14 -> 2028 | C29: =SLOPE($C$22:$C$23,$E$22:$E$23) -> -14.96804 | D29: =INTERCEPT($C$22:$C$23,$E$22:$E$23) -> 102794.09 | E29: =L14 -> 4011.5024 | F29: =C29*E29+D29 -> 42749.761
B30: =C15 -> 2029 | C30: =SLOPE($C$22:$C$23,$E$22:$E$23) -> -14.96804 | D30: =INTERCEPT($C$22:$C$23,$E$22:$E$23) -> 102794.09 | E30: =L15 -> 4269.7762 | F30: =C30*E30+D30 -> 38883.907
B31: =C16 -> 2030 | C31: =SLOPE($C$22:$C$23,$E$22:$E$23) -> -14.96804 | D31: =INTERCEPT($C$22:$C$23,$E$22:$E$23) -> 102794.09 | E31: =L16 -> 4544.6787 | F31: =C31*E31+D31 -> 34769.156
B34: ELASTICIDAD PRECIO DEMANDA
B36: Año | C36: Cantidad | D36: Precio | E36: Var q | F36: Var p | G36: epd | H36: tipo
B37: =B27 -> 2026 | C37: =E27 -> 3540.8776 | D37: =F27 -> 49794.09
B38: =B28 -> 2027 | C38: =E28 -> 3768.8512 | D38: =F28 -> 46381.774 | E38: =ABS((C38-C37)/C37) -> 0.064383333 | F38: =ABS((D38-D37)/D37) -> 0.068528547 | G38: =E38/F38 -> 0.93951114 | H38: elástica
B39: =B29 -> 2028 | C39: =E29 -> 4011.5024 | D39: =F29 -> 42749.761 | E39: =ABS((C39-C38)/C38) -> 0.064383333 | F39: =ABS((D39-D38)/D38) -> 0.078306901 | G39: =E39/F39 -> 0.82219233 | H39: inelástia
B40: =B30 -> 2029 | C40: =E30 -> 4269.7762 | D40: =F30 -> 38883.907 | E40: =ABS((C40-C39)/C39) -> 0.064383333 | F40: =ABS((D40-D39)/D39) -> 0.090429841 | G40: =E40/F40 -> 0.71196999 | H40: inelástia
B41: =B31 -> 2030 | C41: =E31 -> 4544.6787 | D41: =F31 -> 34769.156 | E41: =ABS((C41-C40)/C40) -> 0.064383333 | F41: =ABS((D41-D40)/D40) -> 0.10582143 | G41: =E41/F41 -> 0.60841488 | H41: inelástia
B45: CALCULO DEL P1 SEGÚN ENCUESTA
B46: a | C46: b | D46: c | E46: d | F46: e
B47: Rango | D47: Promedio | E47: % encuesta | F47: Producto-suma
A48: 1 | C48: 30000 | D48: =AVERAGE(B48:C48) -> 30000 | E48: 0 | F48: =D48*E48 -> 0
A49: 2 | B49: 31000 | C49: 40000 | D49: =AVERAGE(B49:C49) -> 35500 | E49: 0.167 | F49: =D49*E49 -> 5928.5
A50: 3 | B50: 41000 | C50: 50000 | D50: =AVERAGE(B50:C50) -> 45500 | E50: 0.083 | F50: =D50*E50 -> 3776.5
A51: 4 | B51: 51000 | C51: 60000 | D51: =AVERAGE(B51:C51) -> 55500 | E51: 0.583 | F51: =D51*E51 -> 32356.5
A52: 5 | B52: 61000 | C52: 70000 | D52: =AVERAGE(B52:C52) -> 65500 | E52: 0.167 | F52: =D52*E52 -> 10938.5
A53: 6 | C53: 71000 | D53: =AVERAGE(B53:C53) -> 71000 | E53: 0 | F53: =D53*E53 -> 0
...

Sheet Oferta
B2: PROYECCIÓN DE OFERTA
B4: Producto | C4: Morral | D4: Dato | E4: Fuente
B5: Cantidad | C5: plataformas que ofrecen servicios de salud en eafit | D5: 4 | E5: Análisis documental, encuestas y entrevistas | F5: 12000 | G5: cantidad de estudiantes en eafit
B6: Productos vendidos | C6: Productor/año | D6: =F5*F6 -> 2952 | E6: Análisis documental, encuestas y entrevistas | F6: 0.246 | G6: Porcentaje de personas dentro de la comunidad eafitense que usa aplicaciones para gestionar la salud.
B7: Total producción | C7: Vendida/año | D7: =D5*D6 -> 11808
B8: Filtro 1 | C8: =Demanda!C6 -> % diispuestos a comprar | D8: =Demanda!D6 -> 0.646 | E8: Encuesta de segmentacion
B9: Filtro 2 | C9: =Demanda!C7 -> % estudiantes que respondieron "Tal vez", teniendo en cuenta que solo el 50% adoptaria la app. | D9: =Demanda!D7 -> 0.123 | E9: Encuesta de segmentacion
B10: Filtro 3 | C10: =Demanda!C8 -> Factor de corrección por intención vs. acción real, (estándar para aplicaciones móviles) | D10: =Demanda!D8 -> 0.7 | E10: Pruebas UX
B11: Total oferta | C11: Año base | D11: =D7*D8*D9*D10 -> 656.76804
B12: Período | C12: Año | D12: PROM IPP | E12: Oferta proyectada
B13: Base | C13: 2023 | E13: =D11 -> 656.76804
B14: 1 | C14: 2024 | D14: ='Indicadores Macro'!$H$11 -> 0.07 | E14: =E13*(1+D14) -> 702.74181
B15: 2 | C15: =C14+1 -> 2025 | D15: ='Indicadores Macro'!$H$11 -> 0.07 | E15: =E14*(1+D15) -> 751.93373
B16: 3 | C16: =C15+1 -> 2026 | D16: ='Indicadores Macro'!$H$11 -> 0.07 | E16: =E15*(1+D16) -> 804.5691
B17: 4 | C17: =C16+1 -> 2027 | D17: ='Indicadores Macro'!$H$11 -> 0.07 | E17: =E16*(1+D17) -> 860.88893
B18: 5 | C18: =C17+1 -> 2028 | D18: ='Indicadores Macro'!$H$11 -> 0.07 | E18: =E17*(1+D18) -> 921.15116
N20: 12000 | O20: 0.246
B21: FUNCIÓN DE LA OFERTA | C21: P = MQ + C | D21: PROM IPP | E21: =D14 -> 0.07
B24: P1 | C24: 53000 | D24: Q1 | E24: =E15 -> 751.93373
B25: P2 | C25: =C24/(1+E21) -> 49532.71 | D25: Q2 | E25: =E14 -> 702.74181
C27: M | D27: C | E27: Q | F27: P
B28: Año | C28: Pendiente | D28: Intercepto | E28: Cantidad | F28: Precio
B29: =C14 -> 2024 | C29: =SLOPE($C$24:$C$25,$E$24:$E$25) -> 70.484934 | D29: =INTERCEPT($C$24:$C$25,$E$24:$E$25) -> 7.2759576e-12 | E29: =E14 -> 702.74181 | F29: =C29*E29+D29 -> 49532.71
B30: =C15 -> 2025 | C30: =SLOPE($C$24:$C$25,$E$24:$E$25) -> 70.484934 | D30: =INTERCEPT($C$24:$C$25,$E$24:$E$25) -> 7.2759576e-12 | E30: =E15 -> 751.93373 | F30: =C30*E30+D30 -> 53000
B31: =C16 -> 2026 | C31: =SLOPE($C$24:$C$25,$E$24:$E$25) -> 70.484934 | D31: =INTERCEPT($C$24:$C$25,$E$24:$E$25) -> 7.2759576e-12 | E31: =E16 -> 804.5691 | F31: =C31*E31+D31 -> 56710
B32: =C17 -> 2027 | C32: =SLOPE($C$24:$C$25,$E$24:$E$25) -> 70.484934 | D32: =INTERCEPT($C$24:$C$25,$E$24:$E$25) -> 7.2759576e-12 | E32: =E17 -> 860.88893 | F32: =C32*E32+D32 -> 60679.7
B33: =C18 -> 2028 | C33: =SLOPE($C$24:$C$25,$E$24:$E$25) -> 70.484934 | D33: =INTERCEPT($C$24:$C$25,$E$24:$E$25) -> 7.2759576e-12 | E33: =E18 -> 921.15116 | F33: =C33*E33+D33 -> 64927.279

Sheet Equilibrio
B2: PUNTO DE EQUILIBRIO
C4: DEMANDA | E4: OFERTA
B5: Año | C5: Cantidad | D5: Precio | E5: Cantidad | F5: Precio
B6: 2024 | C6: =Demanda!E27 -> 3540.8776 | D6: =Demanda!F27 -> 49794.09 | E6: =Oferta!E29 -> 702.74181 | F6: =Oferta!F29 -> 49532.71
B7: =B6+1 -> 2025 | C7: =Demanda!E28 -> 3768.8512 | D7: =Demanda!F28 -> 46381.774 | E7: =Oferta!E30 -> 751.93373 | F7: =Oferta!F30 -> 53000
B8: =B7+1 -> 2026 | C8: =Demanda!E29 -> 4011.5024 | D8: =Demanda!F29 -> 42749.761 | E8: =Oferta!E31 -> 804.5691 | F8: =Oferta!F31 -> 56710
B9: =B8+1 -> 2027 | C9: =Demanda!E30 -> 4269.7762 | D9: =Demanda!F30 -> 38883.907 | E9: =Oferta!E32 -> 860.88893 | F9: =Oferta!F32 -> 60679.7
B10: =B9+1 -> 2028 | C10: =Demanda!E31 -> 4544.6787 | D10: =Demanda!F31 -> 34769.156 | E10: =Oferta!E33 -> 921.15116 | F10: =Oferta!F33 -> 64927.279
C13: pendiente | D13: intercepto
B14: demanda | C14: =-Demanda!C27 -> 14.96804 | D14: =Demanda!D27 -> 102794.09
B15: oferta | C15: =Oferta!C29 -> 70.484934 | D15: =Oferta!D29 -> 7.2759576e-12
C16: =SUM(C14:C15) -> 85.452975 | D16: =SUM(D14:D15) -> 102794.09
B18: cantidad (q) | C18: =D16/C16 -> 1202.9317
B19: precio (p) | C19: =-C14*C18+D14 -> 84788.56

Sheet Brecha O-D
B2: BRECHA DEMANDA Y OFERTA
B4: Período | C4: Demanda proyectada | D4: Oferta proyectada | E4: Brecha
B5: =Demanda!C12 -> 2026 | C5: =Demanda!E12 -> 6875.4906 | D5: =Oferta!E14 -> 702.74181 | E5: =C5-D5 -> 6172.7488
B6: =Demanda!C13 -> 2027 | C6: =Demanda!E13 -> 7318.1576 | D6: =Oferta!E15 -> 751.93373 | E6: =C6-D6 -> 6566.2238
B7: =Demanda!C14 -> 2028 | C7: =Demanda!E14 -> 7789.325 | D7: =Oferta!E16 -> 804.5691 | E7: =C7-D7 -> 6984.7559
B8: =Demanda!C15 -> 2029 | C8: =Demanda!E15 -> 8290.8277 | D8: =Oferta!E17 -> 860.88893 | E8: =C8-D8 -> 7429.9387
B9: =Demanda!C16 -> 2030 | C9: =Demanda!E16 -> 8824.6188 | D9: =Oferta!E18 -> 921.15116 | E9: =C9-D9 -> 7903.4676
B11: Si oferta mayor a demanda | C11: Sobre oferta
B12: Si oferta menor a demanda | C12: Demanda insafistecha
B13: Si oferta similar a demanda | C13: Similar a punto de equilibrio

Sheet Tamaño
B2: TAMAÑO DEL PROYECTO
B4: Producto | C4: Cantidad
B5: Producción diaria | C5: 10
B6: Producción mensual | C6: =C5*24 -> 240
B7: Producción anual | C7: =C6*12 -> 2880
B8: Año | C8: Tamaño | D8: Tasa de proyección
B9: 2024 | C9: =C7 -> 2880 | D9: ='Indicadores Macro'!H11 -> 0.07
B10: 2025 | C10: =C9*(1+$D$9) -> 3081.6 | E10: =C10/Demanda!E12 -> 0.44820074
B11: =B10+1 -> 2026 | C11: =C10*(1+$D$9) -> 3297.312
B12: =B11+1 -> 2027 | C12: =C11*(1+$D$9) -> 3528.1238
B13: =B12+1 -> 2028 | C13: =C12*(1+$D$9) -> 3775.0925
B14: =B13+1 -> 2029 | C14: =C13*(1+$D$9) -> 4039.349

Sheet Costos
B2: COSTOS DEL PRODUCTO O SERVICIO
B4: Elemento del costo | C4: Cantidad | D4: Costo unitario | E4: Factor | F4: Costo asignado
B5: Costos directos
B6: Materiales o insumos | C6: =Tamaño!C6 -> 240 | D6: 0 | F6: =C6*D6 -> 0
B7: Licencias de software y APIs externas | C7: 1 | D7: 1500000 | E7: 1.3883 | F7: =C7*D7*E7 -> 2082450
B8: Programadores/desarrolladores backend | C8: 2 | D8: 3000000 | E8: 1.3883 | F8: =C8*D8*E8 -> 8329800
B9: Programadores frontend | C9: 1 | D9: 2800000 | E9: 1.3883 | F9: =C9*D9*E9 -> 3887240
B10: Costos indirectos
B11: Diseñador UX/UI | C11: 1 | D11: 2500000 | E11: 1.3883 | F11: =C11*D11*E11 -> 3470750
B12: Profesional médico | C12: 1 | D12: 3000000 | E12: 1.3883 | F12: =C12*D12*E12 -> 4164900
B13: Oficina (80%) | C13: 1 | D13: 3000000 | E13: 0.8 | F13: =C13*D13*E13 -> 2400000
B14: Servicios públicos (80%) | C14: 1 | D14: 1200000 | E14: 0.8 | F14: =C14*D14*E14 -> 960000
B15: Útiles y papelería de oficina | C15: 1 | D15: 30000 | F15: =C15*D15 -> 30000
B16: Depreciación equipos planta* | C16: 1 | D16: =F25 -> 140000 | F16: =C16*D16 -> 140000
B17: Total costos mensuales | F17: =SUM(F6:F16) -> 25465140
B18: Nivel de producción mes | F18: =Tamaño!C6 -> 240
B19: Costo unitario total | F19: =F17/F18 -> 106104.75
B21: Equipos y enseres de planta | C21: Cantidad | D21: Costo unitario | E21: Costo total | F21: Depreciación mensual
B22: Computadores portátiles | C22: 3 | D22: 4000000 | E22: =C22*D22 -> 12000000 | F22: =E22*10%/12 -> 100000
B23: Celulares para pruebas de app | C23: 2 | D23: 1200000 | E23: =C23*D23 -> 2400000 | F23: =E23*10%/12 -> 20000
B24: Escritorios y sillas ergonómicas | C24: 3 | D24: 800000 | E24: =C24*D24 -> 2400000 | F24: =E24*10%/12 -> 20000
B25: Totales | E25: =SUM(E22:E24) -> 16800000 | F25: =SUM(F22:F24) -> 140000
B33: Descripción
B34: 2017
B35: 2018
B36: 2019
B37: 2020
B38: 2021
B39: Demanda
B40: 3732
B41: 4105
B42: 4515
B43: 4967
B44: 5464
B45: Costo de la materia prima
B46: 230280561 | C46: =B46/$B$40 -> 61704.33 | D46: =C46*(1+3.9%)^6 -> 77626.308 | E46: 2023 | F46: =C46/$C$64 -> 0.61377865
B47: 253296276
B48: 278595052
B49: 306485409
B50: 337152461
...

Sheet Gastos
B2: GASTOS DE ADMINISTRACIÓN Y VENTA
B4: Elemento del gasto | C4: Cantidad | D4: Gasto unitario | E4: Factor | F4: Gasto asignado
B5: Gastos de administración
B6: Salario gerente | C6: 1 | D6: 4000000 | E6: 1.3883 | F6: =C6*D6*E6 -> 5553200
B7: Salario recursos humanos | C7: 1 | D7: 1500000 | E7: 1.3883 | F7: =C7*D7*E7 -> 2082450
B8: Salario secretaria oficina | C8: 1 | D8: 1400000 | E8: 1.3883 | F8: =C8*D8*E8 -> 1943620
B9: Salario oficios generales | C9: 1 | D9: 1500000 | E9: 1.3883 | F9: =C9*D9*E9 -> 2082450
B10: Servicios públicos oficina (20%) | C10: 1 | D10: =Costos!D13 -> 3000000 | E10: 0.2 | F10: =C10*D10*E10 -> 600000
B11: Arrendamiento oficina (20%) | C11: 1 | D11: =Costos!D14 -> 1200000 | E11: 0.2 | F11: =C11*D11*E11 -> 240000
B12: Útiles y papelería de oficina | C12: 1 | D12: 30000 | F12: =C12*D12 -> 30000
B13: Elementos de aseo oficina | C13: 1 | D13: 80000 | F13: =C13*D13 -> 80000
B14: Depreciación equipos de oficina | C14: 1 | D14: =F28 -> 983333.33 | F14: =C14*D14 -> 983333.33
B15: Gastos de venta
B16: Comunnity manager | C16: 1 | D16: 1750000 | E16: 1.3883 | F16: =C16*D16*E16 -> 2429525
B17: Campaña en redes sociales | C17: 1 | D17: 2500000 | F17: =+D17 -> 2500000
B18: Diseño de contenido promocional | C18: 1 | D18: 1000000 | F18: =+D18 -> 1000000
B19: Gastos de distribución | C19: 1 | D19: =1000000 -> 1000000 | F19: =+D19 -> 1000000
B20: Total gastos mensuales | F20: =SUM(F5:F17) -> 18524578
B21: Nivel de producción mes | F21: =Costos!F18 -> 240
B22: Gasto unitario total | F22: =F20/F21 -> 77185.743
B24: Equipos y enseres de oficina | C24: Cantidad | D24: Costo unitario | E24: Costo total | F24: Depreciación mensual
B25: Mesas, escritorios y sillas | C25: 4 | D25: 4000000 | E25: =C25*D25 -> 16000000 | F25: =E25*10%/12 -> 133333.33
B26: Archivadores | C26: 6 | D26: 1000000 | E26: =C26*D26 -> 6000000 | F26: =E26*10%/12 -> 50000
B27: Equipos de cómputo | C27: 6 | D27: 8000000 | E27: =C27*D27 -> 48000000 | F27: =E27*20%/12 -> 800000
B28: Totales | E28: =SUM(E25:E27) -> 70000000 | F28: =SUM(F25:F27) -> 983333.33

Sheet Precio Proy
B2: PRECIO DE VENTA DEL PRODUCTO O SERVICIO
B4: Tipo de fórmula | C4: Costo unitario | D4: Gasto unitario | E4: Margen | F4: Precio
B5: Margen sobre el costo | C5: =Costos!F19 -> 106104.75 | D5: =Gastos!F22 -> 77185.743 | E5: 0.15 | F5: =(C5+D5)*(1+E5) -> 210784.07
B6: Margen sobre el precio | C6: =C5 -> 106104.75 | D6: =D5 -> 77185.743 | E6: =E5 -> 0.15 | F6: =(C6+D6)/(1-E6) -> 215635.87

Sheet Nómina
G1: Valores de referencia:
G2: Salario mínimo - 2025 | I2: 1300000
G3: Auxilio de transporte - 2025 | I3: 162000
G4: ¿Está exonerado del pago de aportes? | I4: Si
B6: Cargo | C6: Devengado | J6: Deducciones | O6: Neto pagado
C7: Salario básico | D7: Días liquidados | E7: Salario devengado | F7: Horas extras | G7: Recargos nocturnos | H7: Auxilio de transporte | I7: Total devengado | J7: Salud | K7: Pensión | L7: Fondo de solidaridad pensional | M7: Retención en la fuente | N7: Otras deducciones
B8: Programadores frontend | C8: 2000000 | D8: 30 | E8: =(C8/30)*D8 -> 2000000 | F8: 3 | G8: 3 | H8: =IF(C8>$I$2*2,0,($I$3/30*D8)) -> 162000 | I8: =SUM(E8:H8) -> 2162006 | J8: =(I8-H8)*0.04 -> 80000.24 | K8: =(I8-H8)*0.04 -> 80000.24 | L8: =(I8-H8)*(IF(AND(((I8-H8)/$I$2)>=4,((I8-H8)/$I$2)<16),1,IF(AND(((I8-H8)/$I$2)>=16,((I8-H8)/$I$2)<=17),1.2,IF(AND(((I8-H8)/$I$2)>17,((I8-H8)/$I$2)<=18),1.4,IF(AND(((I8-H8)/$I$2)>18,((I8-H8)/$I$2)<=19),1.6,IF(AND(((I8-H8)/$I$2)>19,((I8-H8)/$I$2)<=20),1.8,IF(((I8-H8)/$I$2)>20,2,0))))))/100) -> 0 | M8: 0 | N8: 0 | O8: =I8-J8-K8-L8-M8-N8 -> 2002005.5
B9: Programadores/desarrolladores backend | C9: 2800000 | D9: 30 | E9: =(C9/30)*D9 -> 2800000 | F9: 0 | G9: 0 | H9: =IF(C9>$I$2*2,0,($I$3/30*D9)) -> 0 | I9: =SUM(E9:H9) -> 2800000 | J9: =(I9-H9)*0.04 -> 112000 | K9: =(I9-H9)*0.04 -> 112000 | L9: =(I9-H9)*(IF(AND(((I9-H9)/$I$2)>=4,((I9-H9)/$I$2)<16),1,IF(AND(((I9-H9)/$I$2)>=16,((I9-H9)/$I$2)<=17),1.2,IF(AND(((I9-H9)/$I$2)>17,((I9-H9)/$I$2)<=18),1.4,IF(AND(((I9-H9)/$I$2)>18,((I9-H9)/$I$2)<=19),1.6,IF(AND(((I9-H9)/$I$2)>19,((I9-H9)/$I$2)<=20),1.8,IF(((I9-H9)/$I$2)>20,2,0))))))/100) -> 0 | O9: =I9-J9-K9-L9-M9-N9 -> 2576000
B10: Diseñador UX/UI | C10: 2500000 | D10: 30 | E10: =(C10/30)*D10 -> 2500000 | F10: 0 | G10: 0 | H10: =IF(C10>$I$2*2,0,($I$3/30*D10)) -> 162000 | I10: =SUM(E10:H10) -> 2662000 | J10: =(I10-H10)*0.04 -> 100000 | K10: =(I10-H10)*0.04 -> 100000 | L10: =(I10-H10)*(IF(AND(((I10-H10)/$I$2)>=4,((I10-H10)/$I$2)<16),1,IF(AND(((I10-H10)/$I$2)>=16,((I10-H10)/$I$2)<=17),1.2,IF(AND(((I10-H10)/$I$2)>17,((I10-H10)/$I$2)<=18),1.4,IF(AND(((I10-H10)/$I$2)>18,((I10-H10)/$I$2)<=19),1.6,IF(AND(((I10-H10)/$I$2)>19,((I10-H10)/$I$2)<=20),1.8,IF(((I10-H10)/$I$2)>20,2,0))))))/100) -> 0 | O10: =I10-J10-K10-L10-M10-N10 -> 2462000
B11: Profesional médico | C11: 3000000 | D11: 30 | E11: =(C11/30)*D11 -> 3000000 | F11: 0 | G11: 0 | H11: =IF(C11>$I$2*2,0,($I$3/30*D11)) -> 0 | I11: =SUM(E11:H11) -> 3000000 | J11: =(I11-H11)*0.04 -> 120000 | K11: =(I11-H11)*0.04 -> 120000 | L11: =(I11-H11)*(IF(AND(((I11-H11)/$I$2)>=4,((I11-H11)/$I$2)<16),1,IF(AND(((I11-H11)/$I$2)>=16,((I11-H11)/$I$2)<=17),1.2,IF(AND(((I11-H11)/$I$2)>17,((I11-H11)/$I$2)<=18),1.4,IF(AND(((I11-H11)/$I$2)>18,((I11-H11)/$I$2)<=19),1.6,IF(AND(((I11-H11)/$I$2)>19,((I11-H11)/$I$2)<=20),1.8,IF(((I11-H11)/$I$2)>20,2,0))))))/100) -> 0 | O11: =I11-J11-K11-L11-M11-N11 -> 2760000
B12: Gerente | C12: 4000000 | D12: 30 | E12: =(C12/30)*D12 -> 4000000 | F12: 0 | G12: 0 | H12: =IF(C12>$I$2*2,0,($I$3/30*D12)) -> 0 | I12: =SUM(E12:H12) -> 4000000 | J12: =(I12-H12)*0.04 -> 160000 | K12: =(I12-H12)*0.04 -> 160000 | L12: =(I12-H12)*(IF(AND(((I12-H12)/$I$2)>=4,((I12-H12)/$I$2)<16),1,IF(AND(((I12-H12)/$I$2)>=16,((I12-H12)/$I$2)<=17),1.2,IF(AND(((I12-H12)/$I$2)>17,((I12-H12)/$I$2)<=18),1.4,IF(AND(((I12-H12)/$I$2)>18,((I12-H12)/$I$2)<=19),1.6,IF(AND(((I12-H12)/$I$2)>19,((I12-H12)/$I$2)<=20),1.8,IF(((I12-H12)/$I$2)>20,2,0))))))/100) -> 0 | O12: =I12-J12-K12-L12-M12-N12 -> 3680000
B13: Recursos humanos | C13: 1500000 | D13: 30 | E13: =(C13/30)*D13 -> 1500000 | F13: 0 | G13: 0 | H13: =IF(C13>$I$2*2,0,($I$3/30*D13)) -> 162000 | I13: =SUM(E13:H13) -> 1662000 | J13: =(I13-H13)*0.04 -> 60000 | K13: =(I13-H13)*0.04 -> 60000 | L13: =(I13-H13)*(IF(AND(((I13-H13)/$I$2)>=4,((I13-H13)/$I$2)<16),1,IF(AND(((I13-H13)/$I$2)>=16,((I13-H13)/$I$2)<=17),1.2,IF(AND(((I13-H13)/$I$2)>17,((I13-H13)/$I$2)<=18),1.4,IF(AND(((I13-H13)/$I$2)>18,((I13-H13)/$I$2)<=19),1.6,IF(AND(((I13-H13)/$I$2)>19,((I13-H13)/$I$2)<=20),1.8,IF(((I13-H13)/$I$2)>20,2,0))))))/100) -> 0 | O13: =I13-J13-K13-L13-M13-N13 -> 1542000
B14: Secretaria oficina | C14: 1400000 | D14: 30 | E14: =(C14/30)*D14 -> 1400000 | F14: 0 | G14: 0 | H14: =IF(C14>$I$2*2,0,($I$3/30*D14)) -> 162000 | I14: =SUM(E14:H14) -> 1562000 | J14: =(I14-H14)*0.04 -> 56000 | K14: =(I14-H14)*0.04 -> 56000 | L14: =(I14-H14)*(IF(AND(((I14-H14)/$I$2)>=4,((I14-H14)/$I$2)<16),1,IF(AND(((I14-H14)/$I$2)>=16,((I14-H14)/$I$2)<=17),1.2,IF(AND(((I14-H14)/$I$2)>17,((I14-H14)/$I$2)<=18),1.4,IF(AND(((I14-H14)/$I$2)>18,((I14-H14)/$I$2)<=19),1.6,IF(AND(((I14-H14)/$I$2)>19,((I14-H14)/$I$2)<=20),1.8,IF(((I14-H14)/$I$2)>20,2,0))))))/100) -> 0 | O14: =I14-J14-K14-L14-M14-N14 -> 1450000
B15: Oficios generales | C15: 1500000 | D15: 30 | E15: =(C15/30)*D15 -> 1500000 | F15: 0 | G15: 0 | H15: =IF(C15>$I$2*2,0,($I$3/30*D15)) -> 162000 | I15: =SUM(E15:H15) -> 1662000 | J15: =(I15-H15)*0.04 -> 60000 | K15: =(I15-H15)*0.04 -> 60000 | L15: =(I15-H15)*(IF(AND(((I15-H15)/$I$2)>=4,((I15-H15)/$I$2)<16),1,IF(AND(((I15-H15)/$I$2)>=16,((I15-H15)/$I$2)<=17),1.2,IF(AND(((I15-H15)/$I$2)>17,((I15-H15)/$I$2)<=18),1.4,IF(AND(((I15-H15)/$I$2)>18,((I15-H15)/$I$2)<=19),1.6,IF(AND(((I15-H15)/$I$2)>19,((I15-H15)/$I$2)<=20),1.8,IF(((I15-H15)/$I$2)>20,2,0))))))/100) -> 0 | O15: =I15-J15-K15-L15-M15-N15 -> 1542000
B16: Comunnity manager | C16: 1750000 | D16: 30 | E16: =(C16/30)*D16 -> 1750000 | F16: 0 | G16: 0 | H16: =IF(C16>$I$2*2,0,($I$3/30*D16)) -> 162000 | I16: =SUM(E16:H16) -> 1912000 | J16: =(I16-H16)*0.04 -> 70000 | K16: =(I16-H16)*0.04 -> 70000 | L16: =(I16-H16)*(IF(AND(((I16-H16)/$I$2)>=4,((I16-H16)/$I$2)<16),1,IF(AND(((I16-H16)/$I$2)>=16,((I16-H16)/$I$2)<=17),1.2,IF(AND(((I16-H16)/$I$2)>17,((I16-H16)/$I$2)<=18),1.4,IF(AND(((I16-H16)/$I$2)>18,((I16-H16)/$I$2)<=19),1.6,IF(AND(((I16-H16)/$I$2)>19,((I16-H16)/$I$2)<=20),1.8,IF(((I16-H16)/$I$2)>20,2,0))))))/100) -> 0 | O16: =I16-J16-K16-L16-M16-N16 -> 1772000
B17: Totales | E17: =SUM(E8:E16) -> 20450000 | F17: =SUM(F8:F16) -> 3 | G17: =SUM(G8:G16) -> 3 | H17: =SUM(H8:H16) -> 972000 | I17: =SUM(I8:I16) -> 21422006 | J17: =SUM(J8:J16) -> 818000.24 | K17: =SUM(K8:K16) -> 818000.24 | L17: =SUM(L8:L16) -> 0 | ... O17: =SUM(O8:O16) -> 19786006
I20: Provisiones de nómina a cargo del empleador.
I22: Aportes a pensión | L22: =(I17-H17)*0.12 -> 2454000.7
I23: Aportes a salud | L23: =IF(I4="Si",(SUMIF(I8:I16,">"&I2*10,I8:I16))*0.085,(I17-H17)*0.085) -> 0
I24: Aportes a riesgos laborales | L24: =(I17-H17)*0.00522 -> 106749.03
I25: Sena | L25: =IF(I4="Si",(SUMIF(I8:I16,">"&I2*10,I8:I16))*0.02,(I17-H17)*0.02) -> 0
I26: Icbf | L26: =IF(I4="Si",(SUMIF(I8:I16,">"&I2*10,I8:I16))*0.03,(I17-H17)*0.03) -> 0
I27: Cajas de compensación | L27: =(I17-H17)*0.04 -> 818000.24
I28: Prima de servicios | L28: =I17*0.0833 -> 1784453.1
I29: Cesantía | L29: =I17*0.0833 -> 1784453.1
I30: Intereses sobre cesantías | L30: =L29*0.12 -> 214134.37
I31: Provisón de vacaciones | L31: =(I17-F17-G17-H17)*0.0417 -> 852765
I32: Total provisiones | L32: =SUM(L22:L31) -> 8014555.6

Sheet Escenarios Financiam
B2: COMPARACIÓN DE ESCENARIOS DE FINANCIAMIENTO
B3: Análisis de diferentes estructuras de capital para determinar la más conveniente
B6: INDICADOR / CONCEPTO | C6: Sin Deuda (100% Capital) | D6: Actual (60% Deuda) | E6: Alta Deuda (80% Deuda)
B8: 1. ESTRUCTURA DE CAPITAL
B9: Inversión Total (COP) | C9: ='Flujo de Caja'!C25 -> 1.3093917e+08 | D9: ='Flujo de Caja'!C25 -> 1.3093917e+08 | E9: ='Flujo de Caja'!C25 -> 1.3093917e+08
B10: Deuda (COP) | C10: 0 | D10: ='Flujo de Caja'!C30 -> 78563501 | E10: ='Flujo de Caja'!C25*0.8 -> 1.0475134e+08
B11: Patrimonio (COP) | C11: ='Flujo de Caja'!C25 -> 1.3093917e+08 | D11: ='Flujo de Caja'!C31 -> 52375668 | E11: ='Flujo de Caja'!C25*0.2 -> 26187834
B12: % Deuda | C12: 0 | D12: 0.6 | E12: 0.8
B13: % Patrimonio | C13: 1 | D13: 0.4 | E13: 0.2
B15: 2. COSTOS DE FINANCIAMIENTO
B16: Kd (Costo deuda post-impuesto) | C16: 0 | D16: ='Análisis Financiero'!D11 -> 0.1625 | E16: ='Análisis Financiero'!D11 -> 0.1625
B17: Ke (Costo patrimonio) | C17: ='Flujo de Caja'!C97 -> 0.30562489 | D17: ='Flujo de Caja'!C97 -> 0.30562489 | E17: CALCULAR con β ajustado
B18: WACC | C18: ='Flujo de Caja'!C97 -> 0.30562489 | D18: ='Análisis Financiero'!D13 -> 0.2175 | E18: CALCULAR
B20: 3. INDICADORES DEL PROYECTO
B21: VPN Proyecto (COP) | C21: Recalcular con WACC 30% | D21: ='Flujo de Caja'!C70 -> 57467798 | E21: Recalcular con WACC ajustado
B22: TIR Proyecto (%) | C22: ='Flujo de Caja'!C71 -> 0.37906231 | D22: ='Flujo de Caja'!C71 -> 0.37906231 | E22: ='Flujo de Caja'!C71 -> 0.37906231
B23: Margen TIR-WACC (%) | C23: Calcular | D23: ='Flujo de Caja'!C72 -> 0.16156231 | E23: Calcular
B25: 4. INDICADORES DEL INVERSIONISTA
B26: VPN Inversionista (COP) | C26: ='Flujo de Caja'!C70 -> 57467798 | D26: ='Flujo de Caja'!C95 -> 44419969 | E26: Recalcular FCL Inv
B27: TIR Inversionista (%) | C27: ='Flujo de Caja'!C71 -> 0.37906231 | D27: ='Flujo de Caja'!C96 -> 0.60562489 | E27: Recalcular FCL Inv
B28: Margen TIR-TIO (%) | C28: Calcular | D28: ='Flujo de Caja'!C97 -> 0.30562489 | E28: Calcular
B31: 5. ANÁLISIS DE RIESGO Y VENTAJAS
B32: Apalancamiento Financiero | C32: Nulo | D32: Moderado | E32: Alto
B33: Escudo Fiscal | C33: NO | D33: SÍ (Ahorro impuestos) | E33: SÍ (Mayor ahorro)
B34: Carga Financiera | C34: Nula | D34: Media | E34: Alta
B35: Riesgo de Insolvencia | C35: Bajo | D35: Medio | E35: Alto
B36: Flexibilidad Financiera | C36: Alta | D36: Media | E36: Baja
B37: Costo de Capital | C37: Alto | D37: Medio | E37: Medio-Bajo
B40: CONCLUSIÓN Y RECOMENDACIÓN
B41: Basado en los indicadores VPN, TIR y análisis de riesgo, determinar cuál estructura es más conveniente:
B42: • Sin Deuda: Menor riesgo pero menor rentabilidad (sin escudo fiscal)
B43: • Actual 60%: Balance óptimo entre riesgo-retorno, escudo fiscal moderado
B44: • Alta Deuda 80%: Mayor retorno potencial pero alto riesgo financiero
